Workbook

Sheet LEEME
A1: ICET 2026 - Control de asistencia docente
A2: Autor: Francisco Javier Cortés Cabezas · Coordinador académico · Especialista en Informática y Telemática · Magíster en Educación · Doctorando en Desarrollo de la Educación · I.E. ICET, San Andrés de Tumaco (Nariño, Colombia) · © 2026
A4: RONDA (hoja principal): al abrirla muestra, sin filtros, quién debe estar en cada grupo en la sesión actual.
A5: - Día y sesión se calculan con la hora del dispositivo. En Google Sheets: Archivo > Configuración > zona horaria (GMT-05:00 Bogotá).
A6: - Para consultar otro momento escriba el día y/o la sesión en las celdas amarillas; bórrelas para volver a 'ahora'.
A7: - Marque Estado y Motivo con las listas desplegables. En Excel NO se guardan los registros: para guardar use la aplicación web (Apps Script).
A9: Hojas:
A10: Docentes Lista oficial (57). Preescolar y primaria con su grupo (PDF Dirección de Grupo).
A11: Horario Una fila por docente / día / sesión de 45 min (secundaria: PDF 02-02-2026; primaria: áreas múltiples).
A12: Direccion_Grupo Dinamizadores de cada grupo (PDF Dirección de Grupo 2026). En bachillerato la dirección es dual: ambos responsables.
A13: Matriz_Grupos Para cada día y sesión, quién atiende a cada grupo (consulta rápida o para imprimir).
A14: Motivos Catálogo de justificaciones por categoría (salud, permiso, evento externo, calamidad doméstica, etc.).
... A29: Datos personales de docentes: acceso solo para directivos (Ley 1581 de 2012).

Sheet Ronda
A1: RONDA DE ASISTENCIA DOCENTE - ICET 2026 | K1: minuto | L1: =HOUR(NOW())*60+MINUTE(NOW())
K2: sesión auto | L2: =IF(L1>=MAX(Franjas!$G$2:$G$9),"FUERA DE JORNADA",IFERROR(IF(L1<INDEX(Franjas!$G$2:$G$9,MATCH(L1,Franjas!$F$2:$F$9,1)),MATCH(L1,Franjas!$F$2:$F$9,1),"DESCANSO"),"FUERA DE JORNADA"))
A3: Día | B3: =IF(D3<>"",D3,L3) | E3: ← Día manual (opcional) | K3: día auto | L3: =IFERROR(CHOOSE(WEEKDAY(NOW(),2),"LUNES","MARTES","MIERCOLES","JUEVES","VIERNES"),"FIN DE SEMANA")
A4: Sesión | B4: =IF(D4<>"",D4,L2) | E4: ← Sesión manual 1-8 (opcional) | K4: clave | L4: =B3&"|"&B4
A5: Franja | B5: =IFERROR(INDEX(Franjas!$D$2:$D$9,B4)&" - "&INDEX(Franjas!$E$2:$E$9,B4),"Sin clase en este momento")
A6: Docentes esperados | B6: =COUNTIF(Horario!$S$2:$S$1500,L4)
A7: Hora del dispositivo | B7: =TEXT(NOW(),"HH:mm")
A9: # | B9: Grupo | C9: Dirección de grupo | D9: Docente | E9: Área | F9: Nota (alternancia / equipo) | G9: Estado | H9: Motivo | I9: Observaciones
A10: 1 | B10: =IF($K10="","",INDEX(Horario!$Q$2:$Q$1500,$K10)) | C10: =IF($K10="","",INDEX(Horario!$V$2:$V$1500,$K10)) | D10: =IF($K10="","",INDEX(Horario!$B$2:$B$1500,$K10)) | E10: =IF($K10="","",IF(INDEX(Horario!$K$2:$K$1500,$K10)="","(énfasis)",INDEX(Horario!$K$2:$K$1500,$K10))) | F10: =IF($K10="","",INDEX(Horario!$R$2:$R$1500,$K10)) | K10: =IFERROR(MATCH($L$4&"|"&A10,Horario!$U$2:$U$1500,0),"")
A11: 2 | B11: =IF($K11="","",INDEX(Horario!$Q$2:$Q$1500,$K11)) | C11: =IF($K11="","",INDEX(Horario!$V$2:$V$1500,$K11)) | D11: =IF($K11="","",INDEX(Horario!$B$2:$B$1500,$K11)) | E11: =IF($K11="","",IF(INDEX(Horario!$K$2:$K$1500,$K11)="","(énfasis)",INDEX(Horario!$K$2:$K$1500,$K11))) | F11: =IF($K11="","",INDEX(Horario!$R$2:$R$1500,$K11)) | K11: =IFERROR(MATCH($L$4&"|"&A11,Horario!$U$2:$U$1500,0),"")
A12: 3 | B12: =IF($K12="","",INDEX(Horario!$Q$2:$Q$1500,$K12)) | C12: =IF($K12="","",INDEX(Horario!$V$2:$V$1500,$K12)) | D12: =IF($K12="","",INDEX(Horario!$B$2:$B$1500,$K12)) | E12: =IF($K12="","",IF(INDEX(Horario!$K$2:$K$1500,$K12)="","(énfasis)",INDEX(Horario!$K$2:$K$1500,$K12))) | F12: =IF($K12="","",INDEX(Horario!$R$2:$R$1500,$K12)) | K12: =IFERROR(MATCH($L$4&"|"&A12,Horario!$U$2:$U$1500,0),"")
A13: 4 | B13: =IF($K13="","",INDEX(Horario!$Q$2:$Q$1500,$K13)) | C13: =IF($K13="","",INDEX(Horario!$V$2:$V$1500,$K13)) | D13: =IF($K13="","",INDEX(Horario!$B$2:$B$1500,$K13)) | E13: =IF($K13="","",IF(INDEX(Horario!$K$2:$K$1500,$K13)="","(énfasis)",INDEX(Horario!$K$2:$K$1500,$K13))) | F13: =IF($K13="","",INDEX(Horario!$R$2:$R$1500,$K13)) | K13: =IFERROR(MATCH($L$4&"|"&A13,Horario!$U$2:$U$1500,0),"")
A14: 5 | B14: =IF($K14="","",INDEX(Horario!$Q$2:$Q$1500,$K14)) | C14: =IF($K14="","",INDEX(Horario!$V$2:$V$1500,$K14)) | D14: =IF($K14="","",INDEX(Horario!$B$2:$B$1500,$K14)) | E14: =IF($K14="","",IF(INDEX(Horario!$K$2:$K$1500,$K14)="","(énfasis)",INDEX(Horario!$K$2:$K$1500,$K14))) | F14: =IF($K14="","",INDEX(Horario!$R$2:$R$1500,$K14)) | K14: =IFERROR(MATCH($L$4&"|"&A14,Horario!$U$2:$U$1500,0),"")
A15: 6 | B15: =IF($K15="","",INDEX(Horario!$Q$2:$Q$1500,$K15)) | C15: =IF($K15="","",INDEX(Horario!$V$2:$V$1500,$K15)) | D15: =IF($K15="","",INDEX(Horario!$B$2:$B$1500,$K15)) | E15: =IF($K15="","",IF(INDEX(Horario!$K$2:$K$1500,$K15)="","(énfasis)",INDEX(Horario!$K$2:$K$1500,$K15))) | F15: =IF($K15="","",INDEX(Horario!$R$2:$R$1500,$K15)) | K15: =IFERROR(MATCH($L$4&"|"&A15,Horario!$U$2:$U$1500,0),"")
A16: 7 | B16: =IF($K16="","",INDEX(Horario!$Q$2:$Q$1500,$K16)) | C16: =IF($K16="","",INDEX(Horario!$V$2:$V$1500,$K16)) | D16: =IF($K16="","",INDEX(Horario!$B$2:$B$1500,$K16)) | E16: =IF($K16="","",IF(INDEX(Horario!$K$2:$K$1500,$K16)="","(énfasis)",INDEX(Horario!$K$2:$K$1500,$K16))) | F16: =IF($K16="","",INDEX(Horario!$R$2:$R$1500,$K16)) | K16: =IFERROR(MATCH($L$4&"|"&A16,Horario!$U$2:$U$1500,0),"")
A17: 8 | B17: =IF($K17="","",INDEX(Horario!$Q$2:$Q$1500,$K17)) | C17: =IF($K17="","",INDEX(Horario!$V$2:$V$1500,$K17)) | D17: =IF($K17="","",INDEX(Horario!$B$2:$B$1500,$K17)) | E17: =IF($K17="","",IF(INDEX(Horario!$K$2:$K$1500,$K17)="","(énfasis)",INDEX(Horario!$K$2:$K$1500,$K17))) | F17: =IF($K17="","",INDEX(Horario!$R$2:$R$1500,$K17)) | K17: =IFERROR(MATCH($L$4&"|"&A17,Horario!$U$2:$U$1500,0),"")
A18: 9 | B18: =IF($K18="","",INDEX(Horario!$Q$2:$Q$1500,$K18)) | C18: =IF($K18="","",INDEX(Horario!$V$2:$V$1500,$K18)) | D18: =IF($K18="","",INDEX(Horario!$B$2:$B$1500,$K18)) | E18: =IF($K18="","",IF(INDEX(Horario!$K$2:$K$1500,$K18)="","(énfasis)",INDEX(Horario!$K$2:$K$1500,$K18))) | F18: =IF($K18="","",INDEX(Horario!$R$2:$R$1500,$K18)) | K18: =IFERROR(MATCH($L$4&"|"&A18,Horario!$U$2:$U$1500,0),"")
A19: 10 | B19: =IF($K19="","",INDEX(Horario!$Q$2:$Q$1500,$K19)) | C19: =IF($K19="","",INDEX(Horario!$V$2:$V$1500,$K19)) | D19: =IF($K19="","",INDEX(Horario!$B$2:$B$1500,$K19)) | E19: =IF($K19="","",IF(INDEX(Horario!$K$2:$K$1500,$K19)="","(énfasis)",INDEX(Horario!$K$2:$K$1500,$K19))) | F19: =IF($K19="","",INDEX(Horario!$R$2:$R$1500,$K19)) | K19: =IFERROR(MATCH($L$4&"|"&A19,Horario!$U$2:$U$1500,0),"")
A20: 11 | B20: =IF($K20="","",INDEX(Horario!$Q$2:$Q$1500,$K20)) | C20: =IF($K20="","",INDEX(Horario!$V$2:$V$1500,$K20)) | D20: =IF($K20="","",INDEX(Horario!$B$2:$B$1500,$K20)) | E20: =IF($K20="","",IF(INDEX(Horario!$K$2:$K$1500,$K20)="","(énfasis)",INDEX(Horario!$K$2:$K$1500,$K20))) | F20: =IF($K20="","",INDEX(Horario!$R$2:$R$1500,$K20)) | K20: =IFERROR(MATCH($L$4&"|"&A20,Horario!$U$2:$U$1500,0),"")
A21: 12 | B21: =IF($K21="","",INDEX(Horario!$Q$2:$Q$1500,$K21)) | C21: =IF($K21="","",INDEX(Horario!$V$2:$V$1500,$K21)) | D21: =IF($K21="","",INDEX(Horario!$B$2:$B$1500,$K21)) | E21: =IF($K21="","",IF(INDEX(Horario!$K$2:$K$1500,$K21)="","(énfasis)",INDEX(Horario!$K$2:$K$1500,$K21))) | F21: =IF($K21="","",INDEX(Horario!$R$2:$R$1500,$K21)) | K21: =IFERROR(MATCH($L$4&"|"&A21,Horario!$U$2:$U$1500,0),"")
... A79: 70 | B79: =IF($K79="","",INDEX(Horario!$Q$2:$Q$1500,$K79)) | C79: =IF($K79="","",INDEX(Horario!$V$2:$V$1500,$K79)) | D79: =IF($K79="","",INDEX(Horario!$B$2:$B$1500,$K79)) | E79: =IF($K79="","",IF(INDEX(Horario!$K$2:$K$1500,$K79)="","(énfasis)",INDEX(Horario!$K$2:$K$1500,$K79))) | F79: =IF($K79="","",INDEX(Horario!$R$2:$R$1500,$K79)) | K79: =IFERROR(MATCH($L$4&"|"&A79,Horario!$U$2:$U$1500,0),"")

Sheet Docentes
A1: codigo | B1: n | C1: apellidos | D1: nombres | E1: nombre_completo | F1: nivel | G1: grupo_titular | H1: direccion_grupo | I1: areas | J1: correo | K1: tiene_horario | L1: nota
A2: D001 | B2: 1 | C2: Aguirre Riascos | D2: Jorge Andrés | E2: Aguirre Riascos Jorge Andrés | F2: SECUNDARIA | H2: 7°-3 | I2: TEI | K2: SI
A3: D002 | B3: 2 | C3: Angulo Lucero | D3: Andrés Mauricio | E3: Angulo Lucero Andrés Mauricio | F3: SECUNDARIA | H3: 11°-1 | I3: TEI | K3: SI
A4: D003 | B4: 3 | C4: Arboleda Ortiz | D4: Luz América | E4: Arboleda Ortiz Luz América | F4: SECUNDARIA | H4: 11°-2 | I4: ART | K4: SI
A5: D004 | B5: 4 | C5: Arizala Castro | D5: Roberto Carlos | E5: Arizala Castro Roberto Carlos | F5: SECUNDARIA | H5: 7°-4 | I5: CNA/ERD | K5: SI | L5: Desde el cambio del rector atiende todo el horario (Educación Física y Ciencias Naturales) que tenía Terán | M5: hoy Armero (Docente 2)
A6: D005 | B6: 5 | C6: Bastidas Valencia | D6: Zeneida Judith | E6: Bastidas Valencia Zeneida Judith | F6: SECUNDARIA | H6: 9°-2 | I6: MAT | K6: SI
A7: D006 | B7: 6 | C7: Betancourth Ocampo | D7: Yohana Patricia | E7: Betancourth Ocampo Yohana Patricia | F7: SECUNDARIA | H7: 10°-2 | I7: CSI | K7: SI
A8: D007 | B8: 7 | C8: Casanova Casanova | D8: Johana Andrea | E8: Casanova Casanova Johana Andrea | F8: ORIENTACIÓN | K8: SI | L8: Docente orientadora: sin grupos, trabaja con todos los niveles
A9: D008 | B9: 8 | C9: Casanova Quiñones | D9: Yoli del Carmen | E9: Casanova Quiñones Yoli del Carmen | F9: SECUNDARIA | H9: 8°-2 | I9: ETR | K9: SI
A10: D009 | B10: 9 | C10: Castillo Angulo | D10: Martha Cecilia | E10: Castillo Angulo Martha Cecilia | F10: SECUNDARIA | H10: 7°-3 | I10: ETR | K10: SI
A11: D010 | B11: 10 | C11: Castillo Cuero | D11: Daira Eneida | E11: Castillo Cuero Daira Eneida | F11: SECUNDARIA | H11: 7°-1 | I11: CAS | K11: SI
A12: D011 | B12: 11 | C12: Centeno Zúñiga | D12: Claudia Patricia | E12: Centeno Zúñiga Claudia Patricia | F12: PRIMARIA | G12: 0502 | H12: 5°-2 | K12: SI | L12: Grupo según DIRECCIÓN DE GRUPO 2026
A13: D012 | B13: 12 | C13: Chillambo Quiñones | D13: María Rocío | E13: Chillambo Quiñones María Rocío | F13: SECUNDARIA | H13: 8°-2 | I13: CNA | K13: SI
A14: D013 | B14: 13 | C14: Cortés Salazar | D14: María Ebelice | E14: Cortés Salazar María Ebelice | F14: PRIMARIA | G14: 0201 | H14: 2°-1 | K14: SI | L14: Grupo según DIRECCIÓN DE GRUPO 2026
A15: D014 | B15: 14 | C15: Cuéllar Gallo | D15: Nemesia | E15: Cuéllar Gallo Nemesia | F15: PRIMARIA | G15: 0501 | H15: 5°-1 | K15: SI | L15: Grupo según DIRECCIÓN DE GRUPO 2026
A16: D015 | B16: 15 | C16: Cuero Bamba | D16: Berte Levi | E16: Cuero Bamba Berte Levi | F16: SECUNDARIA | H16: CS 2-2 | I16: ERD | K16: SI
A17: D016 | B17: 16 | C17: Cuero Rincón | D17: Hernando Jesús | E17: Cuero Rincón Hernando Jesús | F17: SECUNDARIA | H17: CS 1-1 | I17: CAS/TEI | K17: SI
A18: D017 | B18: 17 | C18: Escobar Cortés | D18: Liliana | E18: Escobar Cortés Liliana | F18: PRIMARIA | G18: 0504 | H18: 5°-4 | K18: SI | L18: Grupo según DIRECCIÓN DE GRUPO 2026
A19: D018 | B19: 18 | C19: Estacio Estupiñán | D19: Rosario | E19: Estacio Estupiñán Rosario | F19: SECUNDARIA | H19: 9°-1 | I19: ETR | K19: SI
A20: D019 | B20: 19 | C20: Fernández Vélez | D20: Alfredo Enrique | E20: Fernández Vélez Alfredo Enrique | F20: SECUNDARIA | H20: 8°-1 | I20: TEI | K20: SI
A21: D020 | B21: 20 | C21: García Gobea | D21: Saydi Magali | E21: García Gobea Saydi Magali | F21: SECUNDARIA | H21: CS 1-1 | I21: CSI | K21: SI
A22: D021 | B22: 21 | C22: Garzón Quiñones | D22: Sixta Janina | E22: Garzón Quiñones Sixta Janina | F22: PRIMARIA | G22: 0202 | H22: 2°-2 | K22: SI | L22: Grupo según DIRECCIÓN DE GRUPO 2026
A23: D022 | B23: 22 | C23: González Castillo | D23: Jólmer Jimy | E23: González Castillo Jólmer Jimy | F23: SECUNDARIA | H23: 9°-1 | I23: ERD | K23: SI
A24: D023 | B24: 23 | C24: Landázuri Quiñones | D24: María Elia | E24: Landázuri Quiñones María Elia | F24: PRIMARIA | G24: 0101 | H24: 1°-1 | K24: SI | L24: Grupo según DIRECCIÓN DE GRUPO 2026
A25: D024 | B25: 24 | C25: Landázuri Gallón | D25: Teresa | E25: Landázuri Gallón Teresa | F25: PRIMARIA | G25: 0302 | H25: 3°-2 | K25: SI | L25: Grupo según DIRECCIÓN DE GRUPO 2026
A26: D025 | B26: 25 | C26: Lemos Guancha | D26: Miriam | E26: Lemos Guancha Miriam | F26: SECUNDARIA | I26: CNA | K26: SI
A27: D026 | B27: 26 | C27: Lozano Torres | D27: Amanda Inés | E27: Lozano Torres Amanda Inés | F27: SECUNDARIA | H27: 6°-2 | I27: ETR | K27: SI
A28: D027 | B28: 27 | C28: Martínez Álvarez | D28: Andrea Ascención | E28: Martínez Álvarez Andrea Ascención | F28: PREESCOLAR | G28: 0002 | H28: 0°-2 | K28: SI | L28: Grupo según DIRECCIÓN DE GRUPO 2026
A29: D028 | B29: 28 | C29: Meza Banguera | D29: Gladys Alicia | E29: Meza Banguera Gladys Alicia | F29: SECUNDARIA | H29: 10°-1 | I29: CAS | K29: SI
A30: D029 | B30: 29 | C30: Mindineros Satizábal | D30: John Jáver | E30: Mindineros Satizábal John Jáver | F30: SECUNDARIA | H30: 10°-1 | I30: TEI | K30: SI
A31: D030 | B31: 30 | C31: Montaño Anchico | D31: Favio Héctor | E31: Montaño Anchico Favio Héctor | F31: SECUNDARIA | H31: 6°-1 | I31: CAS | K31: SI
A32: D031 | B32: 31 | C32: Montaño Arizala | D32: Leidis Claudina | E32: Montaño Arizala Leidis Claudina | F32: SECUNDARIA | H32: 11°-2 | I32: ETR | K32: SI
A33: D032 | B33: 32 | C33: Narváez Sánchez | D33: Dora Alejandra | E33: Narváez Sánchez Dora Alejandra | F33: PRIMARIA | G33: 0503 | H33: 5°-3 | K33: SI | L33: Grupo según DIRECCIÓN DE GRUPO 2026
A34: D033 | B34: 33 | C34: Núñez Perlaza | D34: Elcy | E34: Núñez Perlaza Elcy | F34: PRIMARIA | G34: 0402 | H34: 4°-2 | K34: SI | L34: Grupo según DIRECCIÓN DE GRUPO 2026
A35: D034 | B35: 34 | C35: Ordóñez Tenorio | D35: Jaime Marcial | E35: Ordóñez Tenorio Jaime Marcial | F35: SECUNDARIA | H35: 7°-1 | I35: CNA | K35: SI
A36: D035 | B36: 35 | C36: Ortiz Araujo | D36: Adiela Carlota | E36: Ortiz Araujo Adiela Carlota | F36: SECUNDARIA | H36: CS 2-1 | I36: CSI | K36: SI
A37: D036 | B37: 36 | C37: Ponce Moncayo | D37: Ángela Paola | E37: Ponce Moncayo Ángela Paola | F37: ORIENTACIÓN | K37: SI | L37: Docente orientadora: sin grupos, trabaja con todos los niveles
A38: D037 | B38: 37 | C38: Prado Quiñones | D38: Genís Maribel | E38: Prado Quiñones Genís Maribel | F38: SECUNDARIA | H38: 7°-2 | I38: ART/CNA | K38: SI | L38: Reemplazo de la docente Luz María Cortés Tenorio. Desde el cambio del rector atiende el horario que tenía Puches (Docente 1)
A39: D038 | B39: 38 | C39: Preciado Torres | D39: Oleisa | E39: Preciado Torres Oleisa | F39: SECUNDARIA | H39: CS 2-1 | I39: MAT | K39: SI
A40: D039 | B40: 39 | C40: Puches | D40: Ana Milena | E40: Puches Ana Milena | F40: SECUNDARIA | H40: CS 1-2 | I40: ART | K40: SI | L40: Desde el cambio del rector atiende el horario que tenía Prado Maribel (Docente 2 de Arte)
...

Sheet Horario
A1: docente_n | B1: docente | C1: dia | D1: hora | E1: bloque | F1: sesion | G1: inicio | H1: fin | I1: tipo | J1: grupo | K1: area | L1: enfasis_ref | M1: grupos_enfasis | N1: equipo_enfasis | O1: alternancia | P1: celda_original | Q1: grupo_mostrar | R1: nota | S1: clave | T1: orden | U1: indice | V1: dir_grupo
A2: 23 | B2: Landázuri Quiñones María Elia | C2: LUNES | D2: 1 | E2: 1 | F2: 1 | G2: 06:30 | H2: 07:15 | I2: AREAS_MULTIPLES | J2: 0101 | K2: ÁREAS MÚLTIPLES | O2: Maestro de aula: todas las áreas con su grupo | Q2: =IF(I2="ENFASIS","ÉNFASIS "&M2,IFERROR(VLOOKUP(J2,Grupos!$A$2:$D$100,4,FALSE),J2)) | R2: =O2&IF(N2<>"",IF(O2<>""," · ","")&"Con: "&N2,"") | S2: =C2&"|"&D2 | T2: =COUNTIF($S$2:S2,S2) | U2: =S2&"|"&T2 | V2: =IFERROR(VLOOKUP(IF(I2="ENFASIS",LEFT(M2,FIND("+",M2&"+")-1),J2),Direccion_Grupo!$A$2:$G$100,7,FALSE),"")
A3: 45 | B3: Sinisterra Ana Lucía | C3: LUNES | D3: 1 | E3: 1 | F3: 1 | G3: 06:30 | H3: 07:15 | I3: AREAS_MULTIPLES | J3: 0102 | K3: ÁREAS MÚLTIPLES | O3: Maestro de aula: todas las áreas con su grupo | Q3: =IF(I3="ENFASIS","ÉNFASIS "&M3,IFERROR(VLOOKUP(J3,Grupos!$A$2:$D$100,4,FALSE),J3)) | R3: =O3&IF(N3<>"",IF(O3<>""," · ","")&"Con: "&N3,"") | S3: =C3&"|"&D3 | T3: =COUNTIF($S$2:S3,S3) | U3: =S3&"|"&T3 | V3: =IFERROR(VLOOKUP(IF(I3="ENFASIS",LEFT(M3,FIND("+",M3&"+")-1),J3),Direccion_Grupo!$A$2:$G$100,7,FALSE),"")
A4: 13 | B4: Cortés Salazar María Ebelice | C4: LUNES | D4: 1 | E4: 1 | F4: 1 | G4: 06:30 | H4: 07:15 | I4: AREAS_MULTIPLES | J4: 0201 | K4: ÁREAS MÚLTIPLES | O4: Maestro de aula: todas las áreas con su grupo | Q4: =IF(I4="ENFASIS","ÉNFASIS "&M4,IFERROR(VLOOKUP(J4,Grupos!$A$2:$D$100,4,FALSE),J4)) | R4: =O4&IF(N4<>"",IF(O4<>""," · ","")&"Con: "&N4,"") | S4: =C4&"|"&D4 | T4: =COUNTIF($S$2:S4,S4) | U4: =S4&"|"&T4 | V4: =IFERROR(VLOOKUP(IF(I4="ENFASIS",LEFT(M4,FIND("+",M4&"+")-1),J4),Direccion_Grupo!$A$2:$G$100,7,FALSE),"")
A5: 21 | B5: Garzón Quiñones Sixta Janina | C5: LUNES | D5: 1 | E5: 1 | F5: 1 | G5: 06:30 | H5: 07:15 | I5: AREAS_MULTIPLES | J5: 0202 | K5: ÁREAS MÚLTIPLES | O5: Maestro de aula: todas las áreas con su grupo | Q5: =IF(I5="ENFASIS","ÉNFASIS "&M5,IFERROR(VLOOKUP(J5,Grupos!$A$2:$D$100,4,FALSE),J5)) | R5: =O5&IF(N5<>"",IF(O5<>""," · ","")&"Con: "&N5,"") | S5: =C5&"|"&D5 | T5: =COUNTIF($S$2:S5,S5) | U5: =S5&"|"&T5 | V5: =IFERROR(VLOOKUP(IF(I5="ENFASIS",LEFT(M5,FIND("+",M5&"+")-1),J5),Direccion_Grupo!$A$2:$G$100,7,FALSE),"")
A6: 46 | B6: Tenorio Cuero Lucy Bivian | C6: LUNES | D6: 1 | E6: 1 | F6: 1 | G6: 06:30 | H6: 07:15 | I6: AREAS_MULTIPLES | J6: 0203 | K6: ÁREAS MÚLTIPLES | O6: Maestro de aula: todas las áreas con su grupo | Q6: =IF(I6="ENFASIS","ÉNFASIS "&M6,IFERROR(VLOOKUP(J6,Grupos!$A$2:$D$100,4,FALSE),J6)) | R6: =O6&IF(N6<>"",IF(O6<>""," · ","")&"Con: "&N6,"") | S6: =C6&"|"&D6 | T6: =COUNTIF($S$2:S6,S6) | U6: =S6&"|"&T6 | V6: =IFERROR(VLOOKUP(IF(I6="ENFASIS",LEFT(M6,FIND("+",M6&"+")-1),J6),Direccion_Grupo!$A$2:$G$100,7,FALSE),"")
A7: 48 | B7: Torres Segura Encarnación | C7: LUNES | D7: 1 | E7: 1 | F7: 1 | G7: 06:30 | H7: 07:15 | I7: AREAS_MULTIPLES | J7: 0301 | K7: ÁREAS MÚLTIPLES | O7: Maestro de aula: todas las áreas con su grupo | Q7: =IF(I7="ENFASIS","ÉNFASIS "&M7,IFERROR(VLOOKUP(J7,Grupos!$A$2:$D$100,4,FALSE),J7)) | R7: =O7&IF(N7<>"",IF(O7<>""," · ","")&"Con: "&N7,"") | S7: =C7&"|"&D7 | T7: =COUNTIF($S$2:S7,S7) | U7: =S7&"|"&T7 | V7: =IFERROR(VLOOKUP(IF(I7="ENFASIS",LEFT(M7,FIND("+",M7&"+")-1),J7),Direccion_Grupo!$A$2:$G$100,7,FALSE),"")
A8: 24 | B8: Landázuri Gallón Teresa | C8: LUNES | D8: 1 | E8: 1 | F8: 1 | G8: 06:30 | H8: 07:15 | I8: AREAS_MULTIPLES | J8: 0302 | K8: ÁREAS MÚLTIPLES | O8: Maestro de aula: todas las áreas con su grupo | Q8: =IF(I8="ENFASIS","ÉNFASIS "&M8,IFERROR(VLOOKUP(J8,Grupos!$A$2:$D$100,4,FALSE),J8)) | R8: =O8&IF(N8<>"",IF(O8<>""," · ","")&"Con: "&N8,"") | S8: =C8&"|"&D8 | T8: =COUNTIF($S$2:S8,S8) | U8: =S8&"|"&T8 | V8: =IFERROR(VLOOKUP(IF(I8="ENFASIS",LEFT(M8,FIND("+",M8&"+")-1),J8),Direccion_Grupo!$A$2:$G$100,7,FALSE),"")
A9: 55 | B9: Zamora Ordóñez Celia Pastora | C9: LUNES | D9: 1 | E9: 1 | F9: 1 | G9: 06:30 | H9: 07:15 | I9: AREAS_MULTIPLES | J9: 0401 | K9: ÁREAS MÚLTIPLES | O9: Maestro de aula: todas las áreas con su grupo | Q9: =IF(I9="ENFASIS","ÉNFASIS "&M9,IFERROR(VLOOKUP(J9,Grupos!$A$2:$D$100,4,FALSE),J9)) | R9: =O9&IF(N9<>"",IF(O9<>""," · ","")&"Con: "&N9,"") | S9: =C9&"|"&D9 | T9: =COUNTIF($S$2:S9,S9) | U9: =S9&"|"&T9 | V9: =IFERROR(VLOOKUP(IF(I9="ENFASIS",LEFT(M9,FIND("+",M9&"+")-1),J9),Direccion_Grupo!$A$2:$G$100,7,FALSE),"")
A10: 33 | B10: Núñez Perlaza Elcy | C10: LUNES | D10: 1 | E10: 1 | F10: 1 | G10: 06:30 | H10: 07:15 | I10: AREAS_MULTIPLES | J10: 0402 | K10: ÁREAS MÚLTIPLES | O10: Maestro de aula: todas las áreas con su grupo | Q10: =IF(I10="ENFASIS","ÉNFASIS "&M10,IFERROR(VLOOKUP(J10,Grupos!$A$2:$D$100,4,FALSE),J10)) | R10: =O10&IF(N10<>"",IF(O10<>""," · ","")&"Con: "&N10,"") | S10: =C10&"|"&D10 | T10: =COUNTIF($S$2:S10,S10) | U10: =S10&"|"&T10 | V10: =IFERROR(VLOOKUP(IF(I10="ENFASIS",LEFT(M10,FIND("+",M10&"+")-1),J10),Direccion_Grupo!$A$2:$G$100,7,FALSE),"")
A11: 14 | B11: Cuéllar Gallo Nemesia | C11: LUNES | D11: 1 | E11: 1 | F11: 1 | G11: 06:30 | H11: 07:15 | I11: AREAS_MULTIPLES | J11: 0501 | K11: ÁREAS MÚLTIPLES | O11: Maestro de aula: todas las áreas con su grupo | Q11: =IF(I11="ENFASIS","ÉNFASIS "&M11,IFERROR(VLOOKUP(J11,Grupos!$A$2:$D$100,4,FALSE),J11)) | R11: =O11&IF(N11<>"",IF(O11<>""," · ","")&"Con: "&N11,"") | S11: =C11&"|"&D11 | T11: =COUNTIF($S$2:S11,S11) | U11: =S11&"|"&T11 | V11: =IFERROR(VLOOKUP(IF(I11="ENFASIS",LEFT(M11,FIND("+",M11&"+")-1),J11),Direccion_Grupo!$A$2:$G$100,7,FALSE),"")
A12: 11 | B12: Centeno Zúñiga Claudia Patricia | C12: LUNES | D12: 1 | E12: 1 | F12: 1 | G12: 06:30 | H12: 07:15 | I12: AREAS_MULTIPLES | J12: 0502 | K12: ÁREAS MÚLTIPLES | O12: Maestro de aula: todas las áreas con su grupo | Q12: =IF(I12="ENFASIS","ÉNFASIS "&M12,IFERROR(VLOOKUP(J12,Grupos!$A$2:$D$100,4,FALSE),J12)) | R12: =O12&IF(N12<>"",IF(O12<>""," · ","")&"Con: "&N12,"") | S12: =C12&"|"&D12 | T12: =COUNTIF($S$2:S12,S12) | U12: =S12&"|"&T12 | V12: =IFERROR(VLOOKUP(IF(I12="ENFASIS",LEFT(M12,FIND("+",M12&"+")-1),J12),Direccion_Grupo!$A$2:$G$100,7,FALSE),"")
A13: 32 | B13: Narváez Sánchez Dora Alejandra | C13: LUNES | D13: 1 | E13: 1 | F13: 1 | G13: 06:30 | H13: 07:15 | I13: AREAS_MULTIPLES | J13: 0503 | K13: ÁREAS MÚLTIPLES | O13: Maestro de aula: todas las áreas con su grupo | Q13: =IF(I13="ENFASIS","ÉNFASIS "&M13,IFERROR(VLOOKUP(J13,Grupos!$A$2:$D$100,4,FALSE),J13)) | R13: =O13&IF(N13<>"",IF(O13<>""," · ","")&"Con: "&N13,"") | S13: =C13&"|"&D13 | T13: =COUNTIF($S$2:S13,S13) | U13: =S13&"|"&T13 | V13: =IFERROR(VLOOKUP(IF(I13="ENFASIS",LEFT(M13,FIND("+",M13&"+")-1),J13),Direccion_Grupo!$A$2:$G$100,7,FALSE),"")
A14: 17 | B14: Escobar Cortés Liliana | C14: LUNES | D14: 1 | E14: 1 | F14: 1 | G14: 06:30 | H14: 07:15 | I14: AREAS_MULTIPLES | J14: 0504 | K14: ÁREAS MÚLTIPLES | O14: Maestro de aula: todas las áreas con su grupo | Q14: =IF(I14="ENFASIS","ÉNFASIS "&M14,IFERROR(VLOOKUP(J14,Grupos!$A$2:$D$100,4,FALSE),J14)) | R14: =O14&IF(N14<>"",IF(O14<>""," · ","")&"Con: "&N14,"") | S14: =C14&"|"&D14 | T14: =COUNTIF($S$2:S14,S14) | U14: =S14&"|"&T14 | V14: =IFERROR(VLOOKUP(IF(I14="ENFASIS",LEFT(M14,FIND("+",M14&"+")-1),J14),Direccion_Grupo!$A$2:$G$100,7,FALSE),"")
A15: 37 | B15: Prado Quiñones Genís Maribel | C15: LUNES | D15: 1 | E15: 1 | F15: 1 | G15: 06:30 | H15: 07:15 | I15: CLASE | J15: 0601 | K15: ART | P15: 0601-ART | Q15: =IF(I15="ENFASIS","ÉNFASIS "&M15,IFERROR(VLOOKUP(J15,Grupos!$A$2:$D$100,4,FALSE),J15)) | R15: =O15&IF(N15<>"",IF(O15<>""," · ","")&"Con: "&N15,"") | S15: =C15&"|"&D15 | T15: =COUNTIF($S$2:S15,S15) | U15: =S15&"|"&T15 | V15: =IFERROR(VLOOKUP(IF(I15="ENFASIS",LEFT(M15,FIND("+",M15&"+")-1),J15),Direccion_Grupo!$A$2:$G$100,7,FALSE),"")
A16: 26 | B16: Lozano Torres Amanda Inés | C16: LUNES | D16: 1 | E16: 1 | F16: 1 | G16: 06:30 | H16: 07:15 | I16: CLASE | J16: 0602 | K16: ETR | O16: Ética / Religión (alternan cada semana) | P16: 0602-ETR | Q16: =IF(I16="ENFASIS","ÉNFASIS "&M16,IFERROR(VLOOKUP(J16,Grupos!$A$2:$D$100,4,FALSE),J16)) | R16: =O16&IF(N16<>"",IF(O16<>""," · ","")&"Con: "&N16,"") | S16: =C16&"|"&D16 | T16: =COUNTIF($S$2:S16,S16) | U16: =S16&"|"&T16 | V16: =IFERROR(VLOOKUP(IF(I16="ENFASIS",LEFT(M16,FIND("+",M16&"+")-1),J16),Direccion_Grupo!$A$2:$G$100,7,FALSE),"")
A17: 39 | B17: Puches Ana Milena | C17: LUNES | D17: 1 | E17: 1 | F17: 1 | G17: 06:30 | H17: 07:15 | I17: CLASE | J17: 0704 | K17: ART | P17: 0704-ART | Q17: =IF(I17="ENFASIS","ÉNFASIS "&M17,IFERROR(VLOOKUP(J17,Grupos!$A$2:$D$100,4,FALSE),J17)) | R17: =O17&IF(N17<>"",IF(O17<>""," · ","")&"Con: "&N17,"") | S17: =C17&"|"&D17 | T17: =COUNTIF($S$2:S17,S17) | U17: =S17&"|"&T17 | V17: =IFERROR(VLOOKUP(IF(I17="ENFASIS",LEFT(M17,FIND("+",M17&"+")-1),J17),Direccion_Grupo!$A$2:$G$100,7,FALSE),"")
A18: 35 | B18: Ortiz Araujo Adiela Carlota | C18: LUNES | D18: 1 | E18: 1 | F18: 1 | G18: 06:30 | H18: 07:15 | I18: CLASE | J18: 0801 | K18: CSI | O18: Sociales / Inglés (alternan cada semana) | P18: 0801-CSI | Q18: =IF(I18="ENFASIS","ÉNFASIS "&M18,IFERROR(VLOOKUP(J18,Grupos!$A$2:$D$100,4,FALSE),J18)) | R18: =O18&IF(N18<>"",IF(O18<>""," · ","")&"Con: "&N18,"") | S18: =C18&"|"&D18 | T18: =COUNTIF($S$2:S18,S18) | U18: =S18&"|"&T18 | V18: =IFERROR(VLOOKUP(IF(I18="ENFASIS",LEFT(M18,FIND("+",M18&"+")-1),J18),Direccion_Grupo!$A$2:$G$100,7,FALSE),"")
A19: 15 | B19: Cuero Bamba Berte Levi | C19: LUNES | D19: 1 | E19: 1 | F19: 1 | G19: 06:30 | H19: 07:15 | I19: CLASE | J19: 0802 | K19: ERD | P19: 0802-ERD | Q19: =IF(I19="ENFASIS","ÉNFASIS "&M19,IFERROR(VLOOKUP(J19,Grupos!$A$2:$D$100,4,FALSE),J19)) | R19: =O19&IF(N19<>"",IF(O19<>""," · ","")&"Con: "&N19,"") | S19: =C19&"|"&D19 | T19: =COUNTIF($S$2:S19,S19) | U19: =S19&"|"&T19 | V19: =IFERROR(VLOOKUP(IF(I19="ENFASIS",LEFT(M19,FIND("+",M19&"+")-1),J19),Direccion_Grupo!$A$2:$G$100,7,FALSE),"")
A20: 6 | B20: Betancourth Ocampo Yohana Patricia | C20: LUNES | D20: 1 | E20: 1 | F20: 1 | G20: 06:30 | H20: 07:15 | I20: CLASE | J20: 0901 | K20: CSI | O20: Sociales / Inglés (alternan cada semana) | P20: 0901-CSI | Q20: =IF(I20="ENFASIS","ÉNFASIS "&M20,IFERROR(VLOOKUP(J20,Grupos!$A$2:$D$100,4,FALSE),J20)) | R20: =O20&IF(N20<>"",IF(O20<>""," · ","")&"Con: "&N20,"") | S20: =C20&"|"&D20 | T20: =COUNTIF($S$2:S20,S20) | U20: =S20&"|"&T20 | V20: =IFERROR(VLOOKUP(IF(I20="ENFASIS",LEFT(M20,FIND("+",M20&"+")-1),J20),Direccion_Grupo!$A$2:$G$100,7,FALSE),"")
A21: 49 | B21: Valencia Marínez Saidy Eufemia | C21: LUNES | D21: 1 | E21: 1 | F21: 1 | G21: 06:30 | H21: 07:15 | I21: CLASE | J21: 0902 | K21: ART | P21: 0902-ART | Q21: =IF(I21="ENFASIS","ÉNFASIS "&M21,IFERROR(VLOOKUP(J21,Grupos!$A$2:$D$100,4,FALSE),J21)) | R21: =O21&IF(N21<>"",IF(O21<>""," · ","")&"Con: "&N21,"") | S21: =C21&"|"&D21 | T21: =COUNTIF($S$2:S21,S21) | U21: =S21&"|"&T21 | V21: =IFERROR(VLOOKUP(IF(I21="ENFASIS",LEFT(M21,FIND("+",M21&"+")-1),J21),Direccion_Grupo!$A$2:$G$100,7,FALSE),"")
A22: 31 | B22: Montaño Arizala Leidis Claudina | C22: LUNES | D22: 1 | E22: 1 | F22: 1 | G22: 06:30 | H22: 07:15 | I22: CLASE | J22: 1002 | K22: ETR | O22: Ética / Religión (alternan cada semana) | P22: 1002-ETR | Q22: =IF(I22="ENFASIS","ÉNFASIS "&M22,IFERROR(VLOOKUP(J22,Grupos!$A$2:$D$100,4,FALSE),J22)) | R22: =O22&IF(N22<>"",IF(O22<>""," · ","")&"Con: "&N22,"") | S22: =C22&"|"&D22 | T22: =COUNTIF($S$2:S22,S22) | U22: =S22&"|"&T22 | V22: =IFERROR(VLOOKUP(IF(I22="ENFASIS",LEFT(M22,FIND("+",M22&"+")-1),J22),Direccion_Grupo!$A$2:$G$100,7,FALSE),"")
A23: 2 | B23: Angulo Lucero Andrés Mauricio | C23: LUNES | D23: 1 | E23: 1 | F23: 1 | G23: 06:30 | H23: 07:15 | I23: CLASE | J23: 1101 | K23: TEI | P23: 1101-TEI | Q23: =IF(I23="ENFASIS","ÉNFASIS "&M23,IFERROR(VLOOKUP(J23,Grupos!$A$2:$D$100,4,FALSE),J23)) | R23: =O23&IF(N23<>"",IF(O23<>""," · ","")&"Con: "&N23,"") | S23: =C23&"|"&D23 | T23: =COUNTIF($S$2:S23,S23) | U23: =S23&"|"&T23 | V23: =IFERROR(VLOOKUP(IF(I23="ENFASIS",LEFT(M23,FIND("+",M23&"+")-1),J23),Direccion_Grupo!$A$2:$G$100,7,FALSE),"")
A24: 40 | B24: Pulgarín Ortiz César Marino | C24: LUNES | D24: 1 | E24: 1 | F24: 1 | G24: 06:30 | H24: 07:15 | I24: CLASE | J24: 1102 | K24: CSI | O24: Sociales / Inglés (alternan cada semana) | P24: 1102-CSI | Q24: =IF(I24="ENFASIS","ÉNFASIS "&M24,IFERROR(VLOOKUP(J24,Grupos!$A$2:$D$100,4,FALSE),J24)) | R24: =O24&IF(N24<>"",IF(O24<>""," · ","")&"Con: "&N24,"") | S24: =C24&"|"&D24 | T24: =COUNTIF($S$2:S24,S24) | U24: =S24&"|"&T24 | V24: =IFERROR(VLOOKUP(IF(I24="ENFASIS",LEFT(M24,FIND("+",M24&"+")-1),J24),Direccion_Grupo!$A$2:$G$100,7,FALSE),"")
A25: 16 | B25: Cuero Rincón Hernando Jesús | C25: LUNES | D25: 1 | E25: 1 | F25: 1 | G25: 06:30 | H25: 07:15 | I25: CLASE | J25: CS101 | K25: CAS | P25: CS101-CAS | Q25: =IF(I25="ENFASIS","ÉNFASIS "&M25,IFERROR(VLOOKUP(J25,Grupos!$A$2:$D$100,4,FALSE),J25)) | R25: =O25&IF(N25<>"",IF(O25<>""," · ","")&"Con: "&N25,"") | S25: =C25&"|"&D25 | T25: =COUNTIF($S$2:S25,S25) | U25: =S25&"|"&T25 | V25: =IFERROR(VLOOKUP(IF(I25="ENFASIS",LEFT(M25,FIND("+",M25&"+")-1),J25),Direccion_Grupo!$A$2:$G$100,7,FALSE),"")
A26: 42 | B26: Quiñones Cabezas Marcos Vidal | C26: LUNES | D26: 1 | E26: 1 | F26: 1 | G26: 06:30 | H26: 07:15 | I26: CLASE | J26: CS102 | K26: TEI | P26: CS102-TEI | Q26: =IF(I26="ENFASIS","ÉNFASIS "&M26,IFERROR(VLOOKUP(J26,Grupos!$A$2:$D$100,4,FALSE),J26)) | R26: =O26&IF(N26<>"",IF(O26<>""," · ","")&"Con: "&N26,"") | S26: =C26&"|"&D26 | T26: =COUNTIF($S$2:S26,S26) | U26: =S26&"|"&T26 | V26: =IFERROR(VLOOKUP(IF(I26="ENFASIS",LEFT(M26,FIND("+",M26&"+")-1),J26),Direccion_Grupo!$A$2:$G$100,7,FALSE),"")
A27: 19 | B27: Fernández Vélez Alfredo Enrique | C27: LUNES | D27: 1 | E27: 1 | F27: 1 | G27: 06:30 | H27: 07:15 | I27: CLASE | J27: CS201 | K27: TEI | P27: CS201-TEI | Q27: =IF(I27="ENFASIS","ÉNFASIS "&M27,IFERROR(VLOOKUP(J27,Grupos!$A$2:$D$100,4,FALSE),J27)) | R27: =O27&IF(N27<>"",IF(O27<>""," · ","")&"Con: "&N27,"") | S27: =C27&"|"&D27 | T27: =COUNTIF($S$2:S27,S27) | U27: =S27&"|"&T27 | V27: =IFERROR(VLOOKUP(IF(I27="ENFASIS",LEFT(M27,FIND("+",M27&"+")-1),J27),Direccion_Grupo!$A$2:$G$100,7,FALSE),"")
A28: 12 | B28: Chillambo Quiñones María Rocío | C28: LUNES | D28: 1 | E28: 1 | F28: 1 | G28: 06:30 | H28: 07:15 | I28: CLASE | J28: CS202 | K28: CNA | P28: CS202-CNA | Q28: =IF(I28="ENFASIS","ÉNFASIS "&M28,IFERROR(VLOOKUP(J28,Grupos!$A$2:$D$100,4,FALSE),J28)) | R28: =O28&IF(N28<>"",IF(O28<>""," · ","")&"Con: "&N28,"") | S28: =C28&"|"&D28 | T28: =COUNTIF($S$2:S28,S28) | U28: =S28&"|"&T28 | V28: =IFERROR(VLOOKUP(IF(I28="ENFASIS",LEFT(M28,FIND("+",M28&"+")-1),J28),Direccion_Grupo!$A$2:$G$100,7,FALSE),"")
A29: 56 | B29: Ortiz Estacio Martha Cecilia | C29: LUNES | D29: 1 | E29: 1 | F29: 1 | G29: 06:30 | H29: 07:15 | I29: TUTORIA | J29: PTAFI | K29: TUTORÍA PTAFI | O29: Jornada 06:30 a 12:00 | Q29: =IF(I29="ENFASIS","ÉNFASIS "&M29,IFERROR(VLOOKUP(J29,Grupos!$A$2:$D$100,4,FALSE),J29)) | R29: =O29&IF(N29<>"",IF(O29<>""," · ","")&"Con: "&N29,"") | S29: =C29&"|"&D29 | T29: =COUNTIF($S$2:S29,S29) | U29: =S29&"|"&T29 | V29: =IFERROR(VLOOKUP(IF(I29="ENFASIS",LEFT(M29,FIND("+",M29&"+")-1),J29),Direccion_Grupo!$A$2:$G$100,7,FALSE),"")
A30: 44 | B30: Samaniego Angulo Flor Mireya | C30: LUNES | D30: 1 | E30: 1 | F30: 1 | G30: 06:30 | H30: 07:15 | I30: ENFASIS | K30: ART | L30: 0701 | M30: 0701 | N30: Valverde Montaño María Teresa (CAS) | O30: PAREJA: comparten el énfasis y alternan por semana | P30: ENFASIS-0701 | Q30: =IF(I30="ENFASIS","ÉNFASIS "&M30,IFERROR(VLOOKUP(J30,Grupos!$A$2:$D$100,4,FALSE),J30)) | R30: =O30&IF(N30<>"",IF(O30<>""," · ","")&"Con: "&N30,"") | S30: =C30&"|"&D30 | T30: =COUNTIF($S$2:S30,S30) | U30: =S30&"|"&T30 | V30: =IFERROR(VLOOKUP(IF(I30="ENFASIS",LEFT(M30,FIND("+",M30&"+")-1),J30),Direccion_Grupo!$A$2:$G$100,7,FALSE),"")
A31: 51 | B31: Valverde Montaño María Teresa | C31: LUNES | D31: 1 | E31: 1 | F31: 1 | G31: 06:30 | H31: 07:15 | I31: ENFASIS | K31: CAS | L31: 0701 | M31: 0701 | N31: Samaniego Angulo Flor Mireya (ART) | O31: PAREJA: comparten el énfasis y alternan por semana | P31: ENFASIS-0701 | Q31: =IF(I31="ENFASIS","ÉNFASIS "&M31,IFERROR(VLOOKUP(J31,Grupos!$A$2:$D$100,4,FALSE),J31)) | R31: =O31&IF(N31<>"",IF(O31<>""," · ","")&"Con: "&N31,"") | S31: =C31&"|"&D31 | T31: =COUNTIF($S$2:S31,S31) | U31: =S31&"|"&T31 | V31: =IFERROR(VLOOKUP(IF(I31="ENFASIS",LEFT(M31,FIND("+",M31&"+")-1),J31),Direccion_Grupo!$A$2:$G$100,7,FALSE),"")
A32: 34 | B32: Ordóñez Tenorio Jaime Marcial | C32: LUNES | D32: 1 | E32: 1 | F32: 1 | G32: 06:30 | H32: 07:15 | I32: ENFASIS | K32: CNA | L32: 0702 | M32: 0702 | N32: Armero Dájome Jesús (ERD) | O32: PAREJA: comparten el énfasis y alternan por semana | P32: ENFASIS-0702 | Q32: =IF(I32="ENFASIS","ÉNFASIS "&M32,IFERROR(VLOOKUP(J32,Grupos!$A$2:$D$100,4,FALSE),J32)) | R32: =O32&IF(N32<>"",IF(O32<>""," · ","")&"Con: "&N32,"") | S32: =C32&"|"&D32 | T32: =COUNTIF($S$2:S32,S32) | U32: =S32&"|"&T32 | V32: =IFERROR(VLOOKUP(IF(I32="ENFASIS",LEFT(M32,FIND("+",M32&"+")-1),J32),Direccion_Grupo!$A$2:$G$100,7,FALSE),"")
A33: 4 | B33: Arizala Castro Roberto Carlos | C33: LUNES | D33: 1 | E33: 1 | F33: 1 | G33: 06:30 | H33: 07:15 | I33: ENFASIS | K33: ERD | L33: 0702 | M33: 0702 | N33: Ordóñez Tenorio Jaime Marcial (CNA) | O33: PAREJA: comparten el énfasis y alternan por semana | P33: ENFASIS-0702 | Q33: =IF(I33="ENFASIS","ÉNFASIS "&M33,IFERROR(VLOOKUP(J33,Grupos!$A$2:$D$100,4,FALSE),J33)) | R33: =O33&IF(N33<>"",IF(O33<>""," · ","")&"Con: "&N33,"") | S33: =C33&"|"&D33 | T33: =COUNTIF($S$2:S33,S33) | U33: =S33&"|"&T33 | V33: =IFERROR(VLOOKUP(IF(I33="ENFASIS",LEFT(M33,FIND("+",M33&"+")-1),J33),Direccion_Grupo!$A$2:$G$100,7,FALSE),"")
A34: 8 | B34: Casanova Quiñones Yoli del Carmen | C34: LUNES | D34: 1 | E34: 1 | F34: 1 | G34: 06:30 | H34: 07:15 | I34: ENFASIS | K34: ETR | L34: 0703 | M34: 0703 | N34: Quintero Ramírez María del Carmen (CSI) | O34: PAREJA: comparten el énfasis y alternan por semana | P34: ENFASIS-0703 | Q34: =IF(I34="ENFASIS","ÉNFASIS "&M34,IFERROR(VLOOKUP(J34,Grupos!$A$2:$D$100,4,FALSE),J34)) | R34: =O34&IF(N34<>"",IF(O34<>""," · ","")&"Con: "&N34,"") | S34: =C34&"|"&D34 | T34: =COUNTIF($S$2:S34,S34) | U34: =S34&"|"&T34 | V34: =IFERROR(VLOOKUP(IF(I34="ENFASIS",LEFT(M34,FIND("+",M34&"+")-1),J34),Direccion_Grupo!$A$2:$G$100,7,FALSE),"")
A35: 41 | B35: Quintero Ramírez María del Carmen | C35: LUNES | D35: 1 | E35: 1 | F35: 1 | G35: 06:30 | H35: 07:15 | I35: ENFASIS | K35: CSI | L35: 0703 | M35: 0703 | N35: Casanova Quiñones Yoli del Carmen (ETR) | O35: PAREJA: comparten el énfasis y alternan por semana | P35: ENFASIS-0703 | Q35: =IF(I35="ENFASIS","ÉNFASIS "&M35,IFERROR(VLOOKUP(J35,Grupos!$A$2:$D$100,4,FALSE),J35)) | R35: =O35&IF(N35<>"",IF(O35<>""," · ","")&"Con: "&N35,"") | S35: =C35&"|"&D35 | T35: =COUNTIF($S$2:S35,S35) | U35: =S35&"|"&T35 | V35: =IFERROR(VLOOKUP(IF(I35="ENFASIS",LEFT(M35,FIND("+",M35&"+")-1),J35),Direccion_Grupo!$A$2:$G$100,7,FALSE),"")
A36: 3 | B36: Arboleda Ortiz Luz América | C36: LUNES | D36: 1 | E36: 1 | F36: 1 | G36: 06:30 | H36: 07:15 | I36: ENFASIS | K36: ART | L36: D5-10° | M36: 1001 | N36: Montaño Anchico Favio Héctor (CAS); Ramírez Guerra Jimmy Eduardo (ERD); Villota Rubio Héctor Hugo (CNA) | O36: EQUIPO DE 4: cada docente atiende un grupo de estudiantes en su área | P36: ENFASIS-D5-10° | Q36: =IF(I36="ENFASIS","ÉNFASIS "&M36,IFERROR(VLOOKUP(J36,Grupos!$A$2:$D$100,4,FALSE),J36)) | R36: =O36&IF(N36<>"",IF(O36<>""," · ","")&"Con: "&N36,"") | S36: =C36&"|"&D36 | T36: =COUNTIF($S$2:S36,S36) | U36: =S36&"|"&T36 | V36: =IFERROR(VLOOKUP(IF(I36="ENFASIS",LEFT(M36,FIND("+",M36&"+")-1),J36),Direccion_Grupo!$A$2:$G$100,7,FALSE),"")
A37: 30 | B37: Montaño Anchico Favio Héctor | C37: LUNES | D37: 1 | E37: 1 | F37: 1 | G37: 06:30 | H37: 07:15 | I37: ENFASIS | K37: CAS | L37: D5-10° | M37: 1001 | N37: Arboleda Ortiz Luz América (ART); Ramírez Guerra Jimmy Eduardo (ERD); Villota Rubio Héctor Hugo (CNA) | O37: EQUIPO DE 4: cada docente atiende un grupo de estudiantes en su área | P37: ENFASIS-D5-10° | Q37: =IF(I37="ENFASIS","ÉNFASIS "&M37,IFERROR(VLOOKUP(J37,Grupos!$A$2:$D$100,4,FALSE),J37)) | R37: =O37&IF(N37<>"",IF(O37<>""," · ","")&"Con: "&N37,"") | S37: =C37&"|"&D37 | T37: =COUNTIF($S$2:S37,S37) | U37: =S37&"|"&T37 | V37: =IFERROR(VLOOKUP(IF(I37="ENFASIS",LEFT(M37,FIND("+",M37&"+")-1),J37),Direccion_Grupo!$A$2:$G$100,7,FALSE),"")
A38: 43 | B38: Ramírez Guerra Jimmy Eduardo | C38: LUNES | D38: 1 | E38: 1 | F38: 1 | G38: 06:30 | H38: 07:15 | I38: ENFASIS | K38: ERD | L38: D5-10° | M38: 1001 | N38: Arboleda Ortiz Luz América (ART); Montaño Anchico Favio Héctor (CAS); Villota Rubio Héctor Hugo (CNA) | O38: EQUIPO DE 4: cada docente atiende un grupo de estudiantes en su área | P38: ENFASIS-D5-10° | Q38: =IF(I38="ENFASIS","ÉNFASIS "&M38,IFERROR(VLOOKUP(J38,Grupos!$A$2:$D$100,4,FALSE),J38)) | R38: =O38&IF(N38<>"",IF(O38<>""," · ","")&"Con: "&N38,"") | S38: =C38&"|"&D38 | T38: =COUNTIF($S$2:S38,S38) | U38: =S38&"|"&T38 | V38: =IFERROR(VLOOKUP(IF(I38="ENFASIS",LEFT(M38,FIND("+",M38&"+")-1),J38),Direccion_Grupo!$A$2:$G$100,7,FALSE),"")
A39: 53 | B39: Villota Rubio Héctor Hugo | C39: LUNES | D39: 1 | E39: 1 | F39: 1 | G39: 06:30 | H39: 07:15 | I39: ENFASIS | K39: CNA | L39: D5-10° | M39: 1001 | N39: Arboleda Ortiz Luz América (ART); Montaño Anchico Favio Héctor (CAS); Ramírez Guerra Jimmy Eduardo (ERD) | O39: EQUIPO DE 4: cada docente atiende un grupo de estudiantes en su área | P39: ENFASIS-D5-10° | Q39: =IF(I39="ENFASIS","ÉNFASIS "&M39,IFERROR(VLOOKUP(J39,Grupos!$A$2:$D$100,4,FALSE),J39)) | R39: =O39&IF(N39<>"",IF(O39<>""," · ","")&"Con: "&N39,"") | S39: =C39&"|"&D39 | T39: =COUNTIF($S$2:S39,S39) | U39: =S39&"|"&T39 | V39: =IFERROR(VLOOKUP(IF(I39="ENFASIS",LEFT(M39,FIND("+",M39&"+")-1),J39),Direccion_Grupo!$A$2:$G$100,7,FALSE),"")
A40: 23 | B40: Landázuri Quiñones María Elia | C40: LUNES | D40: 2 | E40: 1 | F40: 2 | G40: 07:15 | H40: 08:00 | I40: AREAS_MULTIPLES | J40: 0101 | K40: ÁREAS MÚLTIPLES | O40: Maestro de aula: todas las áreas con su grupo | Q40: =IF(I40="ENFASIS","ÉNFASIS "&M40,IFERROR(VLOOKUP(J40,Grupos!$A$2:$D$100,4,FALSE),J40)) | R40: =O40&IF(N40<>"",IF(O40<>""," · ","")&"Con: "&N40,"") | S40: =C40&"|"&D40 | T40: =COUNTIF($S$2:S40,S40) | U40: =S40&"|"&T40 | V40: =IFERROR(VLOOKUP(IF(I40="ENFASIS",LEFT(M40,FIND("+",M40&"+")-1),J40),Direccion_Grupo!$A$2:$G$100,7,FALSE),"")
...

Sheet Matriz_Grupos
A1: día | B1: sesión | C1: franja | D1: 0°-1 | E1: 0°-2 | F1: 1°-1 | G1: 1°-2 | H1: 2°-1 | I1: 2°-2 | J1: 2°-3 | K1: 3°-1 | L1: 3°-2 | M1: 4°-1 | N1: 4°-2 | O1: 5°-1 | P1: 5°-2 | Q1: 5°-3 | R1: 5°-4 | S1: 6°-1 | T1: 6°-2 | U1: CS 1-1 | V1: CS 1-2 | W1: 7°-1 | X1: 7°-2 | Y1: 7°-3 | Z1: 7°-4 | AA1: 8°-1 | AB1: 8°-2 | AC1: 9°-1 | AD1: 9°-2 | AE1: CS 2-1 | AF1: CS 2-2 | AG1: 10°-1 | AH1: 10°-2 | AI1: 11°-1 | AJ1: 11°-2 | AK1: Orientación escolar (todos los niveles) | AL1: Tutora PTAFI (preescolar y primaria)
A2: LUNES | B2: 1 | C2: 06:30-07:15 | F2: Landázuri M. (ÁREAS MÚLTIPLES) | G2: Sinisterra A. (ÁREAS MÚLTIPLES) | H2: Cortés M. (ÁREAS MÚLTIPLES) | I2: Garzón S. (ÁREAS MÚLTIPLES) | J2: Tenorio L. (ÁREAS MÚLTIPLES) | K2: Torres E. (ÁREAS MÚLTIPLES) | L2: Landázuri T. (ÁREAS MÚLTIPLES) | M2: Zamora C. (ÁREAS MÚLTIPLES) | N2: Núñez E. (ÁREAS MÚLTIPLES) | O2: Cuéllar N. (ÁREAS MÚLTIPLES) | P2: Centeno C. (ÁREAS MÚLTIPLES) | Q2: Narváez D. (ÁREAS MÚLTIPLES) | R2: Escobar L. (ÁREAS MÚLTIPLES) | S2: Prado G. (ART) | T2: Lozano A. (ETR) | U2: Cuero H. (CAS) | V2: Quiñones M. (TEI) | W2: ÉNFASIS: Samaniego F. (ART) / Valverde M. (CAS) | X2: ÉNFASIS: Ordóñez J. (CNA) / Arizala R. (ERD) | Y2: ÉNFASIS: Casanova Y. (ETR) / Quintero M. (CSI) | Z2: Puches A. (ART) | AA2: Ortiz A. (CSI) | AB2: Cuero B. (ERD) | AC2: Betancourth Y. (CSI) | AD2: Valencia S. (ART) | AE2: Fernández A. (TEI) | AF2: Chillambo M. (CNA) | AG2: ÉNFASIS: Arboleda L. (ART) / Montaño F. (CAS) / Ramírez J. (ERD) / Villota H. (CNA) | AH2: Montaño L. (ETR) | AI2: Angulo A. (TEI) | AJ2: Pulgarín C. (CSI) | AL2: Ortiz M. (TUTORÍA PTAFI)
A3: LUNES | B3: 2 | C3: 07:15-08:00 | F3: Landázuri M. (ÁREAS MÚLTIPLES) | G3: Sinisterra A. (ÁREAS MÚLTIPLES) | H3: Cortés M. (ÁREAS MÚLTIPLES) | I3: Garzón S. (ÁREAS MÚLTIPLES) | J3: Tenorio L. (ÁREAS MÚLTIPLES) | K3: Torres E. (ÁREAS MÚLTIPLES) | L3: Landázuri T. (ÁREAS MÚLTIPLES) | M3: Zamora C. (ÁREAS MÚLTIPLES) | N3: Núñez E. (ÁREAS MÚLTIPLES) | O3: Cuéllar N. (ÁREAS MÚLTIPLES) | P3: Centeno C. (ÁREAS MÚLTIPLES) | Q3: Narváez D. (ÁREAS MÚLTIPLES) | R3: Escobar L. (ÁREAS MÚLTIPLES) | S3: Prado G. (ART) | T3: Lozano A. (ETR) | U3: Cuero H. (CAS) | V3: Quiñones M. (TEI) | W3: ÉNFASIS: Samaniego F. (ART) / Valverde M. (CAS) | X3: ÉNFASIS: Ordóñez J. (CNA) / Arizala R. (ERD) | Y3: ÉNFASIS: Casanova Y. (ETR) / Quintero M. (CSI) | Z3: Puches A. (ART) | AA3: Ortiz A. (CSI) | AB3: Cuero B. (ERD) | AC3: Betancourth Y. (CSI) | AD3: Valencia S. (ART) | AE3: Fernández A. (TEI) | AF3: Chillambo M. (CNA) | AG3: ÉNFASIS: Arboleda L. (ART) / Montaño F. (CAS) / Ramírez J. (ERD) / Villota H. (CNA) | AH3: Montaño L. (ETR) | AI3: Angulo A. (TEI) | AJ3: Pulgarín C. (CSI) | AK3: Casanova J. (ORIENTACIÓN ESCOLAR) | AL3: Ortiz M. (TUTORÍA PTAFI)
A4: LUNES | B4: 3 | C4: 08:20-09:05 | D4: Valencia G. (ÁREAS MÚLTIPLES) | E4: Martínez A. (ÁREAS MÚLTIPLES) | F4: Landázuri M. (ÁREAS MÚLTIPLES) | G4: Sinisterra A. (ÁREAS MÚLTIPLES) | H4: Cortés M. (ÁREAS MÚLTIPLES) | I4: Garzón S. (ÁREAS MÚLTIPLES) | J4: Tenorio L. (ÁREAS MÚLTIPLES) | K4: Torres E. (ÁREAS MÚLTIPLES) | L4: Landázuri T. (ÁREAS MÚLTIPLES) | M4: Zamora C. (ÁREAS MÚLTIPLES) | N4: Núñez E. (ÁREAS MÚLTIPLES) | O4: Cuéllar N. (ÁREAS MÚLTIPLES) | P4: Centeno C. (ÁREAS MÚLTIPLES) | Q4: Narváez D. (ÁREAS MÚLTIPLES) | R4: Escobar L. (ÁREAS MÚLTIPLES) | S4: Cuero H. (CAS) | T4: Prado G. (ART) | U4: Lozano A. (ETR) | V4: Armero J. (ERD) | W4: Vásquez S. (MAT) | X4: Arizala R. (ERD) | Y4: Ordóñez J. (CNA) | Z4: Casanova Y. (ETR) | AA4: Fernández A. (TEI) | AB4: Valverde M. (CAS) | AC4: ÉNFASIS: González J. (ERD) / Lemos M. (CNA) / Meza G. (CAS) / Valencia S. (ART) | AD4: Mindineros J. (TEI) | AE4: Samaniego F. (ART) | AF4: Preciado O. (MAT) | AG4: Betancourth Y. (CSI) | AH4: Arboleda L. (ART) | AI4: Villota H. (CNA) | AJ4: ÉNFASIS: Angulo A. (TEI) / Montaño L. (ETR) / Pulgarín C. (CSI) / Villota J. (MAT) | AK4: Casanova J. (ORIENTACIÓN ESCOLAR) / Ponce Á. (ORIENTACIÓN ESCOLAR) | AL4: Ortiz M. (TUTORÍA PTAFI)
A5: LUNES | B5: 4 | C5: 09:05-09:50 | D5: Valencia G. (ÁREAS MÚLTIPLES) | E5: Martínez A. (ÁREAS MÚLTIPLES) | F5: Landázuri M. (ÁREAS MÚLTIPLES) | G5: Sinisterra A. (ÁREAS MÚLTIPLES) | H5: Cortés M. (ÁREAS MÚLTIPLES) | I5: Garzón S. (ÁREAS MÚLTIPLES) | J5: Tenorio L. (ÁREAS MÚLTIPLES) | K5: Torres E. (ÁREAS MÚLTIPLES) | L5: Landázuri T. (ÁREAS MÚLTIPLES) | M5: Zamora C. (ÁREAS MÚLTIPLES) | N5: Núñez E. (ÁREAS MÚLTIPLES) | O5: Cuéllar N. (ÁREAS MÚLTIPLES) | P5: Centeno C. (ÁREAS MÚLTIPLES) | Q5: Narváez D. (ÁREAS MÚLTIPLES) | R5: Escobar L. (ÁREAS MÚLTIPLES) | S5: Cuero H. (CAS) | T5: Prado G. (ART) | U5: Lozano A. (ETR) | V5: Armero J. (ERD) | W5: Vásquez S. (MAT) | X5: Arizala R. (ERD) | Y5: Ordóñez J. (CNA) | Z5: Casanova Y. (ETR) | AA5: Fernández A. (TEI) | AB5: Valverde M. (CAS) | AC5: ÉNFASIS: González J. (ERD) / Lemos M. (CNA) / Meza G. (CAS) / Valencia S. (ART) | AD5: Mindineros J. (TEI) | AE5: Samaniego F. (ART) | AF5: Preciado O. (MAT) | AG5: Betancourth Y. (CSI) | AH5: Arboleda L. (ART) | AI5: Villota H. (CNA) | AJ5: ÉNFASIS: Angulo A. (TEI) / Montaño L. (ETR) / Pulgarín C. (CSI) / Villota J. (MAT) | AK5: Casanova J. (ORIENTACIÓN ESCOLAR) / Ponce Á. (ORIENTACIÓN ESCOLAR) | AL5: Ortiz M. (TUTORÍA PTAFI)
A6: LUNES | B6: 5 | C6: 10:10-10:55 | D6: Valencia G. (ÁREAS MÚLTIPLES) | E6: Martínez A. (ÁREAS MÚLTIPLES) | F6: Landázuri M. (ÁREAS MÚLTIPLES) | G6: Sinisterra A. (ÁREAS MÚLTIPLES) | H6: Cortés M. (ÁREAS MÚLTIPLES) | I6: Garzón S. (ÁREAS MÚLTIPLES) | J6: Tenorio L. (ÁREAS MÚLTIPLES) | K6: Torres E. (ÁREAS MÚLTIPLES) | L6: Landázuri T. (ÁREAS MÚLTIPLES) | M6: Zamora C. (ÁREAS MÚLTIPLES) | N6: Núñez E. (ÁREAS MÚLTIPLES) | O6: Cuéllar N. (ÁREAS MÚLTIPLES) | P6: Centeno C. (ÁREAS MÚLTIPLES) | Q6: Narváez D. (ÁREAS MÚLTIPLES) | R6: Escobar L. (ÁREAS MÚLTIPLES) | S6: Armero J. (ERD) | T6: García S. (CSI) | U6: Quiñones M. (TEI) | V6: Cuero H. (CAS) | W6: Puches A. (ART) | X6: Ordóñez J. (CNA) | Y6: Arizala R. (ERD) | Z6: ÉNFASIS: Aguirre J. (TEI) / Vásquez S. (MAT) | AA6: Cuero B. (ERD) | AB6: ÉNFASIS: Castillo M. (ETR) / Fernández A. (TEI) / Ortiz A. (CSI) / Preciado O. (MAT) | AC6: ÉNFASIS: González J. (ERD) / Lemos M. (CNA) / Meza G. (CAS) / Valencia S. (ART) | AD6: Betancourth Y. (CSI) | AE6: Chillambo M. (CNA) | AF6: Samaniego F. (ART) | AG6: Estacio R. (ETR) | AH6: ÉNFASIS: Angulo A. (TEI) / Montaño L. (ETR) / Pulgarín C. (CSI) / Villota J. (MAT) | AI6: Montaño F. (CAS) | AJ6: Ramírez J. (ERD) | AK6: Casanova J. (ORIENTACIÓN ESCOLAR) / Ponce Á. (ORIENTACIÓN ESCOLAR) | AL6: Ortiz M. (TUTORÍA PTAFI)
A7: LUNES | B7: 6 | C7: 10:55-11:40 | D7: Valencia G. (ÁREAS MÚLTIPLES) | E7: Martínez A. (ÁREAS MÚLTIPLES) | F7: Landázuri M. (ÁREAS MÚLTIPLES) | G7: Sinisterra A. (ÁREAS MÚLTIPLES) | H7: Cortés M. (ÁREAS MÚLTIPLES) | I7: Garzón S. (ÁREAS MÚLTIPLES) | J7: Tenorio L. (ÁREAS MÚLTIPLES) | K7: Torres E. (ÁREAS MÚLTIPLES) | L7: Landázuri T. (ÁREAS MÚLTIPLES) | M7: Zamora C. (ÁREAS MÚLTIPLES) | N7: Núñez E. (ÁREAS MÚLTIPLES) | O7: Cuéllar N. (ÁREAS MÚLTIPLES) | P7: Centeno C. (ÁREAS MÚLTIPLES) | Q7: Narváez D. (ÁREAS MÚLTIPLES) | R7: Escobar L. (ÁREAS MÚLTIPLES) | S7: Armero J. (ERD) | T7: García S. (CSI) | U7: Quiñones M. (TEI) | V7: Cuero H. (CAS) | W7: Puches A. (ART) | X7: Ordóñez J. (CNA) | Y7: Arizala R. (ERD) | Z7: ÉNFASIS: Aguirre J. (TEI) / Vásquez S. (MAT) | AA7: Cuero B. (ERD) | AB7: ÉNFASIS: Castillo M. (ETR) / Fernández A. (TEI) / Ortiz A. (CSI) / Preciado O. (MAT) | AC7: ÉNFASIS: González J. (ERD) / Lemos M. (CNA) / Meza G. (CAS) / Valencia S. (ART) | AD7: Betancourth Y. (CSI) | AE7: Chillambo M. (CNA) | AF7: Samaniego F. (ART) | AG7: Estacio R. (ETR) | AH7: ÉNFASIS: Angulo A. (TEI) / Montaño L. (ETR) / Pulgarín C. (CSI) / Villota J. (MAT) | AI7: Montaño F. (CAS) | AJ7: Ramírez J. (ERD) | AK7: Casanova J. (ORIENTACIÓN ESCOLAR) / Ponce Á. (ORIENTACIÓN ESCOLAR) | AL7: Ortiz M. (TUTORÍA PTAFI)
A8: LUNES | B8: 7 | C8: 12:00-12:45 | S8: García S. (CSI) | T8: Cuero H. (CAS) | U8: Armero J. (ERD) | V8: Quiñones M. (MAT) | W8: Ordóñez J. (CNA) | X8: Aguirre J. (TEI) | Y8: Casanova Y. (ETR) | Z8: Castillo D. (CAS) | AA8: Preciado O. (MAT) | AB8: Chillambo M. (CNA) | AC8: Estacio R. (ETR) | AD8: Bastidas Z. (MAT) | AE8: ÉNFASIS: González J. (ERD) / Lemos M. (CNA) / Meza G. (CAS) / Valencia S. (ART) | AF8: Valverde M. (CAS) | AG8: Mindineros J. (TEI) | AH8: Angulo A. (TEI) | AI8: ÉNFASIS: Arboleda L. (ART) / Montaño F. (CAS) / Ramírez J. (ERD) / Villota H. (CNA) | AJ8: Montaño L. (ETR) | AK8: Casanova J. (ORIENTACIÓN ESCOLAR) / Ponce Á. (ORIENTACIÓN ESCOLAR)
A9: LUNES | B9: 8 | C9: 12:45-13:30 | S9: García S. (CSI) | T9: Cuero H. (CAS) | U9: Armero J. (ERD) | V9: Quiñones M. (MAT) | W9: Ordóñez J. (CNA) | X9: Aguirre J. (TEI) | Y9: Casanova Y. (ETR) | Z9: Castillo D. (CAS) | AA9: Preciado O. (MAT) | AB9: Chillambo M. (CNA) | AC9: Estacio R. (ETR) | AD9: Bastidas Z. (MAT) | AE9: ÉNFASIS: González J. (ERD) / Lemos M. (CNA) / Meza G. (CAS) / Valencia S. (ART) | AF9: Valverde M. (CAS) | AG9: Mindineros J. (TEI) | AH9: Angulo A. (TEI) | AI9: ÉNFASIS: Arboleda L. (ART) / Montaño F. (CAS) / Ramírez J. (ERD) / Villota H. (CNA) | AJ9: Montaño L. (ETR) | AK9: Casanova J. (ORIENTACIÓN ESCOLAR) / Ponce Á. (ORIENTACIÓN ESCOLAR)
A10: MARTES | B10: 1 | C10: 06:30-07:15 | F10: Landázuri M. (ÁREAS MÚLTIPLES) | G10: Sinisterra A. (ÁREAS MÚLTIPLES) | H10: Cortés M. (ÁREAS MÚLTIPLES) | I10: Garzón S. (ÁREAS MÚLTIPLES) | J10: Tenorio L. (ÁREAS MÚLTIPLES) | K10: Torres E. (ÁREAS MÚLTIPLES) | L10: Landázuri T. (ÁREAS MÚLTIPLES) | M10: Zamora C. (ÁREAS MÚLTIPLES) | N10: Núñez E. (ÁREAS MÚLTIPLES) | O10: Cuéllar N. (ÁREAS MÚLTIPLES) | P10: Centeno C. (ÁREAS MÚLTIPLES) | Q10: Narváez D. (ÁREAS MÚLTIPLES) | R10: Escobar L. (ÁREAS MÚLTIPLES) | S10: Quiñones M. (MAT) | T10: Cuero H. (TEI) | U10: ÉNFASIS: García S. (CSI) / Lozano A. (ETR) | V10: ÉNFASIS: Aguirre J. (TEI) / Vásquez S. (MAT) | W10: ÉNFASIS: Castillo D. (CAS) / Puches A. (ART) | X10: ÉNFASIS: Chillambo M. (CNA) / Cuero B. (ERD) | Y10: ÉNFASIS: Casanova Y. (ETR) / Quintero M. (CSI) | Z10: Arizala R. (ERD) | AA10: Valverde M. (CAS) | AB10: Preciado O. (MAT) | AC10: Valencia S. (ART) | AD10: ÉNFASIS: Bastidas Z. (MAT) / Betancourth Y. (CSI) / Estacio R. (ETR) / Mindineros J. (TEI) | AE10: Ortiz A. (CSI) | AF10: Fernández A. (TEI) | AG10: Lemos M. (CNA) | AH10: Montaño F. (CAS) | AI10: Ramírez J. (ERD) | AJ10: ÉNFASIS: Angulo A. (TEI) / Montaño L. (ETR) / Pulgarín C. (CSI) / Villota J. (MAT) | AL10: Ortiz M. (TUTORÍA PTAFI)
A11: MARTES | B11: 2 | C11: 07:15-08:00 | F11: Landázuri M. (ÁREAS MÚLTIPLES) | G11: Sinisterra A. (ÁREAS MÚLTIPLES) | H11: Cortés M. (ÁREAS MÚLTIPLES) | I11: Garzón S. (ÁREAS MÚLTIPLES) | J11: Tenorio L. (ÁREAS MÚLTIPLES) | K11: Torres E. (ÁREAS MÚLTIPLES) | L11: Landázuri T. (ÁREAS MÚLTIPLES) | M11: Zamora C. (ÁREAS MÚLTIPLES) | N11: Núñez E. (ÁREAS MÚLTIPLES) | O11: Cuéllar N. (ÁREAS MÚLTIPLES) | P11: Centeno C. (ÁREAS MÚLTIPLES) | Q11: Narváez D. (ÁREAS MÚLTIPLES) | R11: Escobar L. (ÁREAS MÚLTIPLES) | S11: Quiñones M. (MAT) | T11: Cuero H. (TEI) | U11: ÉNFASIS: García S. (CSI) / Lozano A. (ETR) | V11: ÉNFASIS: Aguirre J. (TEI) / Vásquez S. (MAT) | W11: ÉNFASIS: Castillo D. (CAS) / Puches A. (ART) | X11: ÉNFASIS: Chillambo M. (CNA) / Cuero B. (ERD) | Y11: ÉNFASIS: Casanova Y. (ETR) / Quintero M. (CSI) | Z11: Arizala R. (ERD) | AA11: Valverde M. (CAS) | AB11: Preciado O. (MAT) | AC11: Valencia S. (ART) | AD11: ÉNFASIS: Bastidas Z. (MAT) / Betancourth Y. (CSI) / Estacio R. (ETR) / Mindineros J. (TEI) | AE11: Ortiz A. (CSI) | AF11: Fernández A. (TEI) | AG11: Lemos M. (CNA) | AH11: Montaño F. (CAS) | AI11: Ramírez J. (ERD) | AJ11: ÉNFASIS: Angulo A. (TEI) / Montaño L. (ETR) / Pulgarín C. (CSI) / Villota J. (MAT) | AK11: Casanova J. (ORIENTACIÓN ESCOLAR) | AL11: Ortiz M. (TUTORÍA PTAFI)
A12: MARTES | B12: 3 | C12: 08:20-09:05 | D12: Valencia G. (ÁREAS MÚLTIPLES) | E12: Martínez A. (ÁREAS MÚLTIPLES) | F12: Landázuri M. (ÁREAS MÚLTIPLES) | G12: Sinisterra A. (ÁREAS MÚLTIPLES) | H12: Cortés M. (ÁREAS MÚLTIPLES) | I12: Garzón S. (ÁREAS MÚLTIPLES) | J12: Tenorio L. (ÁREAS MÚLTIPLES) | K12: Torres E. (ÁREAS MÚLTIPLES) | L12: Landázuri T. (ÁREAS MÚLTIPLES) | M12: Zamora C. (ÁREAS MÚLTIPLES) | N12: Núñez E. (ÁREAS MÚLTIPLES) | O12: Cuéllar N. (ÁREAS MÚLTIPLES) | P12: Centeno C. (ÁREAS MÚLTIPLES) | Q12: Narváez D. (ÁREAS MÚLTIPLES) | R12: Escobar L. (ÁREAS MÚLTIPLES) | S12: Prado G. (CNA) | T12: Cuero H. (CAS) | U12: Quiñones M. (MAT) | V12: Lozano A. (ETR) | W12: Vásquez S. (MAT) | X12: Aguirre J. (TEI) | Y12: Puches A. (ART) | Z12: Quintero M. (CSI) | AA12: ÉNFASIS: Chillambo M. (CNA) / Cuero B. (ERD) / Samaniego F. (ART) / Valverde M. (CAS) | AB12: Castillo M. (ETR) | AC12: Estacio R. (ETR) | AD12: Bastidas Z. (MAT) | AE12: ÉNFASIS: González J. (ERD) / Lemos M. (CNA) / Meza G. (CAS) / Valencia S. (ART) | AF12: Ortiz A. (CSI) | AG12: Mindineros J. (TEI) | AH12: Angulo A. (TEI) | AI12: ÉNFASIS: Arboleda L. (ART) / Montaño F. (CAS) / Ramírez J. (ERD) / Villota H. (CNA) | AJ12: Pulgarín C. (CSI) | AK12: Casanova J. (ORIENTACIÓN ESCOLAR) / Ponce Á. (ORIENTACIÓN ESCOLAR) | AL12: Ortiz M. (TUTORÍA PTAFI)
A13: MARTES | B13: 4 | C13: 09:05-09:50 | D13: Valencia G. (ÁREAS MÚLTIPLES) | E13: Martínez A. (ÁREAS MÚLTIPLES) | F13: Landázuri M. (ÁREAS MÚLTIPLES) | G13: Sinisterra A. (ÁREAS MÚLTIPLES) | H13: Cortés M. (ÁREAS MÚLTIPLES) | I13: Garzón S. (ÁREAS MÚLTIPLES) | J13: Tenorio L. (ÁREAS MÚLTIPLES) | K13: Torres E. (ÁREAS MÚLTIPLES) | L13: Landázuri T. (ÁREAS MÚLTIPLES) | M13: Zamora C. (ÁREAS MÚLTIPLES) | N13: Núñez E. (ÁREAS MÚLTIPLES) | O13: Cuéllar N. (ÁREAS MÚLTIPLES) | P13: Centeno C. (ÁREAS MÚLTIPLES) | Q13: Narváez D. (ÁREAS MÚLTIPLES) | R13: Escobar L. (ÁREAS MÚLTIPLES) | S13: Prado G. (CNA) | T13: Cuero H. (CAS) | U13: Quiñones M. (MAT) | V13: Lozano A. (ETR) | W13: Vásquez S. (MAT) | X13: Aguirre J. (TEI) | Y13: Puches A. (ART) | Z13: Quintero M. (CSI) | AA13: ÉNFASIS: Chillambo M. (CNA) / Cuero B. (ERD) / Samaniego F. (ART) / Valverde M. (CAS) | AB13: Castillo M. (ETR) | AC13: Estacio R. (ETR) | AD13: Bastidas Z. (MAT) | AE13: ÉNFASIS: González J. (ERD) / Lemos M. (CNA) / Meza G. (CAS) / Valencia S. (ART) | AF13: Ortiz A. (CSI) | AG13: Mindineros J. (TEI) | AH13: Angulo A. (TEI) | AI13: ÉNFASIS: Arboleda L. (ART) / Montaño F. (CAS) / Ramírez J. (ERD) / Villota H. (CNA) | AJ13: Pulgarín C. (CSI) | AK13: Casanova J. (ORIENTACIÓN ESCOLAR) / Ponce Á. (ORIENTACIÓN ESCOLAR) | AL13: Ortiz M. (TUTORÍA PTAFI)
A14: MARTES | B14: 5 | C14: 10:10-10:55 | D14: Valencia G. (ÁREAS MÚLTIPLES) | E14: Martínez A. (ÁREAS MÚLTIPLES) | F14: Landázuri M. (ÁREAS MÚLTIPLES) | G14: Sinisterra A. (ÁREAS MÚLTIPLES) | H14: Cortés M. (ÁREAS MÚLTIPLES) | I14: Garzón S. (ÁREAS MÚLTIPLES) | J14: Tenorio L. (ÁREAS MÚLTIPLES) | K14: Torres E. (ÁREAS MÚLTIPLES) | L14: Landázuri T. (ÁREAS MÚLTIPLES) | M14: Zamora C. (ÁREAS MÚLTIPLES) | N14: Núñez E. (ÁREAS MÚLTIPLES) | O14: Cuéllar N. (ÁREAS MÚLTIPLES) | P14: Centeno C. (ÁREAS MÚLTIPLES) | Q14: Narváez D. (ÁREAS MÚLTIPLES) | R14: Escobar L. (ÁREAS MÚLTIPLES) | S14: Cuero H. (TEI) | T14: Prado G. (CNA) | U14: García S. (CSI) | V14: Armero J. (ERD) | W14: Puches A. (ART) | X14: Castillo D. (CAS) | Y14: Quintero M. (CSI) | Z14: ÉNFASIS: Fernández A. (TEI) / Preciado O. (MAT) | AA14: Castillo M. (ETR) | AB14: Samaniego F. (ART) | AC14: Meza G. (CAS) | AD14: Lemos M. (CNA) | AE14: Valverde M. (CAS) | AF14: ÉNFASIS: Bastidas Z. (MAT) / Betancourth Y. (CSI) / Estacio R. (ETR) / Mindineros J. (TEI) | AG14: González J. (ERD) | AH14: ÉNFASIS: Angulo A. (TEI) / Montaño L. (ETR) / Pulgarín C. (CSI) / Villota J. (MAT) | AI14: Arboleda L. (ART) | AJ14: Villota H. (CNA) | AK14: Casanova J. (ORIENTACIÓN ESCOLAR) / Ponce Á. (ORIENTACIÓN ESCOLAR) | AL14: Ortiz M. (TUTORÍA PTAFI)
A15: MARTES | B15: 6 | C15: 10:55-11:40 | D15: Valencia G. (ÁREAS MÚLTIPLES) | E15: Martínez A. (ÁREAS MÚLTIPLES) | F15: Landázuri M. (ÁREAS MÚLTIPLES) | G15: Sinisterra A. (ÁREAS MÚLTIPLES) | H15: Cortés M. (ÁREAS MÚLTIPLES) | I15: Garzón S. (ÁREAS MÚLTIPLES) | J15: Tenorio L. (ÁREAS MÚLTIPLES) | K15: Torres E. (ÁREAS MÚLTIPLES) | L15: Landázuri T. (ÁREAS MÚLTIPLES) | M15: Zamora C. (ÁREAS MÚLTIPLES) | N15: Núñez E. (ÁREAS MÚLTIPLES) | O15: Cuéllar N. (ÁREAS MÚLTIPLES) | P15: Centeno C. (ÁREAS MÚLTIPLES) | Q15: Narváez D. (ÁREAS MÚLTIPLES) | R15: Escobar L. (ÁREAS MÚLTIPLES) | S15: Cuero H. (TEI) | T15: Prado G. (CNA) | U15: García S. (CSI) | V15: Armero J. (ERD) | W15: Puches A. (ART) | X15: Castillo D. (CAS) | Y15: Quintero M. (CSI) | Z15: ÉNFASIS: Fernández A. (TEI) / Preciado O. (MAT) | AA15: Castillo M. (ETR) | AB15: Samaniego F. (ART) | AC15: Meza G. (CAS) | AD15: Lemos M. (CNA) | AE15: Valverde M. (CAS) | AF15: ÉNFASIS: Bastidas Z. (MAT) / Betancourth Y. (CSI) / Estacio R. (ETR) / Mindineros J. (TEI) | AG15: González J. (ERD) | AH15: ÉNFASIS: Angulo A. (TEI) / Montaño L. (ETR) / Pulgarín C. (CSI) / Villota J. (MAT) | AI15: Arboleda L. (ART) | AJ15: Villota H. (CNA) | AK15: Casanova J. (ORIENTACIÓN ESCOLAR) / Ponce Á. (ORIENTACIÓN ESCOLAR) | AL15: Ortiz M. (TUTORÍA PTAFI)
A16: MARTES | B16: 7 | C16: 12:00-12:45 | S16: ÉNFASIS: Castillo D. (CAS) / Puches A. (ART) | T16: ÉNFASIS: Ordóñez J. (CNA) / Arizala R. (ERD) | U16: Prado G. (ART) | V16: Armero J. (CNA) | W16: Quintero M. (CSI) | X16: Vásquez S. (MAT) | Y16: Casanova Y. (ETR) | Z16: Aguirre J. (TEI) | AA16: Chillambo M. (CNA) | AB16: Valverde M. (CAS) | AC16: ÉNFASIS: González J. (ERD) / Lemos M. (CNA) / Meza G. (CAS) / Valencia S. (ART) | AD16: Estacio R. (ETR) | AE16: Preciado O. (MAT) | AF16: Castillo M. (ETR) | AG16: ÉNFASIS: Arboleda L. (ART) / Montaño F. (CAS) / Ramírez J. (ERD) / Villota H. (CNA) | AH16: Pulgarín C. (CSI) | AI16: Villota J. (MAT) | AJ16: Angulo A. (TEI) | AK16: Casanova J. (ORIENTACIÓN ESCOLAR) / Ponce Á. (ORIENTACIÓN ESCOLAR)
A17: MARTES | B17: 8 | C17: 12:45-13:30 | S17: ÉNFASIS: Castillo D. (CAS) / Puches A. (ART) | T17: ÉNFASIS: Ordóñez J. (CNA) / Arizala R. (ERD) | U17: Prado G. (ART) | V17: Armero J. (CNA) | W17: Quintero M. (CSI) | X17: Vásquez S. (MAT) | Y17: Casanova Y. (ETR) | Z17: Aguirre J. (TEI) | AA17: Chillambo M. (CNA) | AB17: Valverde M. (CAS) | AC17: ÉNFASIS: González J. (ERD) / Lemos M. (CNA) / Meza G. (CAS) / Valencia S. (ART) | AD17: Estacio R. (ETR) | AE17: Preciado O. (MAT) | AF17: Castillo M. (ETR) | AG17: ÉNFASIS: Arboleda L. (ART) / Montaño F. (CAS) / Ramírez J. (ERD) / Villota H. (CNA) | AH17: Pulgarín C. (CSI) | AI17: Villota J. (MAT) | AJ17: Angulo A. (TEI) | AK17: Casanova J. (ORIENTACIÓN ESCOLAR) / Ponce Á. (ORIENTACIÓN ESCOLAR)
A18: MIERCOLES | B18: 1 | C18: 06:30-07:15 | F18: Landázuri M. (ÁREAS MÚLTIPLES) | G18: Sinisterra A. (ÁREAS MÚLTIPLES) | H18: Cortés M. (ÁREAS MÚLTIPLES) | I18: Garzón S. (ÁREAS MÚLTIPLES) | J18: Tenorio L. (ÁREAS MÚLTIPLES) | K18: Torres E. (ÁREAS MÚLTIPLES) | L18: Landázuri T. (ÁREAS MÚLTIPLES) | M18: Zamora C. (ÁREAS MÚLTIPLES) | N18: Núñez E. (ÁREAS MÚLTIPLES) | O18: Cuéllar N. (ÁREAS MÚLTIPLES) | P18: Centeno C. (ÁREAS MÚLTIPLES) | Q18: Narváez D. (ÁREAS MÚLTIPLES) | R18: Escobar L. (ÁREAS MÚLTIPLES) | S18: Prado G. (ART) | T18: Armero J. (ERD) | U18: ÉNFASIS: García S. (CSI) / Lozano A. (ETR) | V18: ÉNFASIS: Aguirre J. (TEI) / Vásquez S. (MAT) | W18: ÉNFASIS: Castillo D. (CAS) / Puches A. (ART) | X18: ÉNFASIS: Chillambo M. (CNA) / Cuero B. (ERD) | Y18: ÉNFASIS: Casanova Y. (ETR) / Quintero M. (CSI) | Z18: Ordóñez J. (CNA) | AA18: Valverde M. (CAS) | AB18: Fernández A. (TEI) | AC18: Bastidas Z. (MAT) | AD18: Meza G. (CAS) | AE18: Samaniego F. (ART) | AF18: Ortiz A. (CSI) | AG18: González J. (ERD) | AH18: Villota H. (CNA) | AI18: Montaño L. (ETR) | AJ18: Arboleda L. (ART) | AL18: Ortiz M. (TUTORÍA PTAFI)
A19: MIERCOLES | B19: 2 | C19: 07:15-08:00 | F19: Landázuri M. (ÁREAS MÚLTIPLES) | G19: Sinisterra A. (ÁREAS MÚLTIPLES) | H19: Cortés M. (ÁREAS MÚLTIPLES) | I19: Garzón S. (ÁREAS MÚLTIPLES) | J19: Tenorio L. (ÁREAS MÚLTIPLES) | K19: Torres E. (ÁREAS MÚLTIPLES) | L19: Landázuri T. (ÁREAS MÚLTIPLES) | M19: Zamora C. (ÁREAS MÚLTIPLES) | N19: Núñez E. (ÁREAS MÚLTIPLES) | O19: Cuéllar N. (ÁREAS MÚLTIPLES) | P19: Centeno C. (ÁREAS MÚLTIPLES) | Q19: Narváez D. (ÁREAS MÚLTIPLES) | R19: Escobar L. (ÁREAS MÚLTIPLES) | S19: Prado G. (ART) | T19: Armero J. (ERD) | U19: ÉNFASIS: García S. (CSI) / Lozano A. (ETR) | V19: ÉNFASIS: Aguirre J. (TEI) / Vásquez S. (MAT) | W19: ÉNFASIS: Castillo D. (CAS) / Puches A. (ART) | X19: ÉNFASIS: Chillambo M. (CNA) / Cuero B. (ERD) | Y19: ÉNFASIS: Casanova Y. (ETR) / Quintero M. (CSI) | Z19: Ordóñez J. (CNA) | AA19: Valverde M. (CAS) | AB19: Fernández A. (TEI) | AC19: Bastidas Z. (MAT) | AD19: Meza G. (CAS) | AE19: Samaniego F. (ART) | AF19: Ortiz A. (CSI) | AG19: González J. (ERD) | AH19: Villota H. (CNA) | AI19: Montaño L. (ETR) | AJ19: Arboleda L. (ART) | AK19: Casanova J. (ORIENTACIÓN ESCOLAR) | AL19: Ortiz M. (TUTORÍA PTAFI)
A20: MIERCOLES | B20: 3 | C20: 08:20-09:05 | D20: Valencia G. (ÁREAS MÚLTIPLES) | E20: Martínez A. (ÁREAS MÚLTIPLES) | F20: Landázuri M. (ÁREAS MÚLTIPLES) | G20: Sinisterra A. (ÁREAS MÚLTIPLES) | H20: Cortés M. (ÁREAS MÚLTIPLES) | I20: Garzón S. (ÁREAS MÚLTIPLES) | J20: Tenorio L. (ÁREAS MÚLTIPLES) | K20: Torres E. (ÁREAS MÚLTIPLES) | L20: Landázuri T. (ÁREAS MÚLTIPLES) | M20: Zamora C. (ÁREAS MÚLTIPLES) | N20: Núñez E. (ÁREAS MÚLTIPLES) | O20: Cuéllar N. (ÁREAS MÚLTIPLES) | P20: Centeno C. (ÁREAS MÚLTIPLES) | Q20: Narváez D. (ÁREAS MÚLTIPLES) | R20: Escobar L. (ÁREAS MÚLTIPLES) | S20: Cuero H. (CAS) | T20: Prado G. (ART) | U20: Armero J. (CNA) | V20: García S. (CSI) | W20: Castillo D. (CAS) | X20: Puches A. (ART) | Y20: Ordóñez J. (CNA) | Z20: Arizala R. (ERD) | AA20: ÉNFASIS: Chillambo M. (CNA) / Cuero B. (ERD) / Samaniego F. (ART) / Valverde M. (CAS) | AB20: Ortiz A. (CSI) | AC20: Valencia S. (ART) | AD20: González J. (ERD) | AE20: Castillo M. (ETR) | AF20: ÉNFASIS: Bastidas Z. (MAT) / Betancourth Y. (CSI) / Estacio R. (ETR) / Mindineros J. (TEI) | AG20: Meza G. (CAS) | AH20: Montaño F. (CAS) | AI20: Arboleda L. (ART) | AJ20: ÉNFASIS: Angulo A. (TEI) / Montaño L. (ETR) / Pulgarín C. (CSI) / Villota J. (MAT) | AK20: Casanova J. (ORIENTACIÓN ESCOLAR) / Ponce Á. (ORIENTACIÓN ESCOLAR) | AL20: Ortiz M. (TUTORÍA PTAFI)
