Workbook

Sheet Ubicacion
A1: UBICACIÓN DE DOCENTES · BACHILLERATO · ICET 2026 | K1: fecha efectiva | L1: =IF(B3<>"",B3,TODAY())
A2: Al abrir muestra sola quién está en cada grupo AHORA. Para consultar otro momento use las celdas amarillas (vacías = ahora). | K2: día | L2: =IFERROR(CHOOSE(WEEKDAY(L1,2),"LUNES","MARTES","MIERCOLES","JUEVES","VIERNES"),"FIN DE SEMANA")
A3: Fecha | C3: ← opcional: escriba otra fecha (dd/mm/aaaa) | K3: minuto | L3: =HOUR(NOW())*60+MINUTE(NOW())
A4: Bloque (90 min) | C4: ← opcional: bloque 1 a 4 | K4: sesión auto | L4: =IF(L3>=MAX(Franjas!$F$2:$F$9),"FUERA DE JORNADA",IFERROR(IF(L3<INDEX(Franjas!$F$2:$F$9,MATCH(L3,Franjas!$E$2:$E$9,1)),MATCH(L3,Franjas!$E$2:$E$9,1),"DESCANSO"),"FUERA DE JORNADA"))
A5: Sesión (45 min) | C5: ← opcional: sesión 1 a 8 (manda sobre el bloque) | K5: sesión manual | L5: =IF(B5<>"",B5,IF(B4<>"",(B4-1)*2+1,""))
K6: sesión efectiva | L6: =IF(L5<>"",L5,IF(L1=TODAY(),L4,"ELEGIR"))
A7: Consulta | B7: =TEXT(L1,"dd/mm/yyyy")&" · "&L2 | K7: clave | L7: =IF(ISNUMBER(L6),L2&"|"&L6,"")
A8: Franja | B8: =IF(ISNUMBER(L6),INDEX(Franjas!$C$2:$C$9,L6)&" - "&INDEX(Franjas!$D$2:$D$9,L6)&" (bloque "&INDEX(Franjas!$B$2:$B$9,L6)&", sesión "&L6&")","—")
A9: Estado | B9: =IF(L2="FIN DE SEMANA","Fin de semana: no hay clases",IF(L6="ELEGIR","Elija un bloque o una sesión para esa fecha",IF(L6="DESCANSO","Descanso: no hay clases en este momento",IF(L6="FUERA DE JORNADA","Fuera de la jornada escolar",IF(L5<>"","Consulta manual","AHORA (automático)")))))
A10: Docentes con clase | B10: =IF(L7="",0,COUNTIF(Horario_Bach!$N$2:$N$1200,L7))
A11: Hora del dispositivo | B11: =TEXT(NOW(),"HH:mm")
A13: # | B13: Grupo | C13: Docente | D13: Área | E13: Tipo | F13: Nota (alternancia / equipo del énfasis)
A14: 1 | B14: =IF($H14="","",INDEX(Horario_Bach!$L$2:$L$1200,$H14)) | C14: =IF($H14="","",INDEX(Horario_Bach!$B$2:$B$1200,$H14)) | D14: =IF($H14="","",INDEX(Horario_Bach!$H$2:$H$1200,$H14)) | E14: =IF($H14="","",IF(INDEX(Horario_Bach!$F$2:$F$1200,$H14)="ENFASIS","Énfasis","Clase")) | F14: =IF($H14="","",INDEX(Horario_Bach!$M$2:$M$1200,$H14)) | H14: =IFERROR(MATCH($L$7&"|"&A14,Horario_Bach!$P$2:$P$1200,0),"")
A15: 2 | B15: =IF($H15="","",INDEX(Horario_Bach!$L$2:$L$1200,$H15)) | C15: =IF($H15="","",INDEX(Horario_Bach!$B$2:$B$1200,$H15)) | D15: =IF($H15="","",INDEX(Horario_Bach!$H$2:$H$1200,$H15)) | E15: =IF($H15="","",IF(INDEX(Horario_Bach!$F$2:$F$1200,$H15)="ENFASIS","Énfasis","Clase")) | F15: =IF($H15="","",INDEX(Horario_Bach!$M$2:$M$1200,$H15)) | H15: =IFERROR(MATCH($L$7&"|"&A15,Horario_Bach!$P$2:$P$1200,0),"")
A16: 3 | B16: =IF($H16="","",INDEX(Horario_Bach!$L$2:$L$1200,$H16)) | C16: =IF($H16="","",INDEX(Horario_Bach!$B$2:$B$1200,$H16)) | D16: =IF($H16="","",INDEX(Horario_Bach!$H$2:$H$1200,$H16)) | E16: =IF($H16="","",IF(INDEX(Horario_Bach!$F$2:$F$1200,$H16)="ENFASIS","Énfasis","Clase")) | F16: =IF($H16="","",INDEX(Horario_Bach!$M$2:$M$1200,$H16)) | H16: =IFERROR(MATCH($L$7&"|"&A16,Horario_Bach!$P$2:$P$1200,0),"")
A17: 4 | B17: =IF($H17="","",INDEX(Horario_Bach!$L$2:$L$1200,$H17)) | C17: =IF($H17="","",INDEX(Horario_Bach!$B$2:$B$1200,$H17)) | D17: =IF($H17="","",INDEX(Horario_Bach!$H$2:$H$1200,$H17)) | E17: =IF($H17="","",IF(INDEX(Horario_Bach!$F$2:$F$1200,$H17)="ENFASIS","Énfasis","Clase")) | F17: =IF($H17="","",INDEX(Horario_Bach!$M$2:$M$1200,$H17)) | H17: =IFERROR(MATCH($L$7&"|"&A17,Horario_Bach!$P$2:$P$1200,0),"")
A18: 5 | B18: =IF($H18="","",INDEX(Horario_Bach!$L$2:$L$1200,$H18)) | C18: =IF($H18="","",INDEX(Horario_Bach!$B$2:$B$1200,$H18)) | D18: =IF($H18="","",INDEX(Horario_Bach!$H$2:$H$1200,$H18)) | E18: =IF($H18="","",IF(INDEX(Horario_Bach!$F$2:$F$1200,$H18)="ENFASIS","Énfasis","Clase")) | F18: =IF($H18="","",INDEX(Horario_Bach!$M$2:$M$1200,$H18)) | H18: =IFERROR(MATCH($L$7&"|"&A18,Horario_Bach!$P$2:$P$1200,0),"")
A19: 6 | B19: =IF($H19="","",INDEX(Horario_Bach!$L$2:$L$1200,$H19)) | C19: =IF($H19="","",INDEX(Horario_Bach!$B$2:$B$1200,$H19)) | D19: =IF($H19="","",INDEX(Horario_Bach!$H$2:$H$1200,$H19)) | E19: =IF($H19="","",IF(INDEX(Horario_Bach!$F$2:$F$1200,$H19)="ENFASIS","Énfasis","Clase")) | F19: =IF($H19="","",INDEX(Horario_Bach!$M$2:$M$1200,$H19)) | H19: =IFERROR(MATCH($L$7&"|"&A19,Horario_Bach!$P$2:$P$1200,0),"")
A20: 7 | B20: =IF($H20="","",INDEX(Horario_Bach!$L$2:$L$1200,$H20)) | C20: =IF($H20="","",INDEX(Horario_Bach!$B$2:$B$1200,$H20)) | D20: =IF($H20="","",INDEX(Horario_Bach!$H$2:$H$1200,$H20)) | E20: =IF($H20="","",IF(INDEX(Horario_Bach!$F$2:$F$1200,$H20)="ENFASIS","Énfasis","Clase")) | F20: =IF($H20="","",INDEX(Horario_Bach!$M$2:$M$1200,$H20)) | H20: =IFERROR(MATCH($L$7&"|"&A20,Horario_Bach!$P$2:$P$1200,0),"")
A21: 8 | B21: =IF($H21="","",INDEX(Horario_Bach!$L$2:$L$1200,$H21)) | C21: =IF($H21="","",INDEX(Horario_Bach!$B$2:$B$1200,$H21)) | D21: =IF($H21="","",INDEX(Horario_Bach!$H$2:$H$1200,$H21)) | E21: =IF($H21="","",IF(INDEX(Horario_Bach!$F$2:$F$1200,$H21)="ENFASIS","Énfasis","Clase")) | F21: =IF($H21="","",INDEX(Horario_Bach!$M$2:$M$1200,$H21)) | H21: =IFERROR(MATCH($L$7&"|"&A21,Horario_Bach!$P$2:$P$1200,0),"")
A22: 9 | B22: =IF($H22="","",INDEX(Horario_Bach!$L$2:$L$1200,$H22)) | C22: =IF($H22="","",INDEX(Horario_Bach!$B$2:$B$1200,$H22)) | D22: =IF($H22="","",INDEX(Horario_Bach!$H$2:$H$1200,$H22)) | E22: =IF($H22="","",IF(INDEX(Horario_Bach!$F$2:$F$1200,$H22)="ENFASIS","Énfasis","Clase")) | F22: =IF($H22="","",INDEX(Horario_Bach!$M$2:$M$1200,$H22)) | H22: =IFERROR(MATCH($L$7&"|"&A22,Horario_Bach!$P$2:$P$1200,0),"")
A23: 10 | B23: =IF($H23="","",INDEX(Horario_Bach!$L$2:$L$1200,$H23)) | C23: =IF($H23="","",INDEX(Horario_Bach!$B$2:$B$1200,$H23)) | D23: =IF($H23="","",INDEX(Horario_Bach!$H$2:$H$1200,$H23)) | E23: =IF($H23="","",IF(INDEX(Horario_Bach!$F$2:$F$1200,$H23)="ENFASIS","Énfasis","Clase")) | F23: =IF($H23="","",INDEX(Horario_Bach!$M$2:$M$1200,$H23)) | H23: =IFERROR(MATCH($L$7&"|"&A23,Horario_Bach!$P$2:$P$1200,0),"")
A24: 11 | B24: =IF($H24="","",INDEX(Horario_Bach!$L$2:$L$1200,$H24)) | C24: =IF($H24="","",INDEX(Horario_Bach!$B$2:$B$1200,$H24)) | D24: =IF($H24="","",INDEX(Horario_Bach!$H$2:$H$1200,$H24)) | E24: =IF($H24="","",IF(INDEX(Horario_Bach!$F$2:$F$1200,$H24)="ENFASIS","Énfasis","Clase")) | F24: =IF($H24="","",INDEX(Horario_Bach!$M$2:$M$1200,$H24)) | H24: =IFERROR(MATCH($L$7&"|"&A24,Horario_Bach!$P$2:$P$1200,0),"")
A25: 12 | B25: =IF($H25="","",INDEX(Horario_Bach!$L$2:$L$1200,$H25)) | C25: =IF($H25="","",INDEX(Horario_Bach!$B$2:$B$1200,$H25)) | D25: =IF($H25="","",INDEX(Horario_Bach!$H$2:$H$1200,$H25)) | E25: =IF($H25="","",IF(INDEX(Horario_Bach!$F$2:$F$1200,$H25)="ENFASIS","Énfasis","Clase")) | F25: =IF($H25="","",INDEX(Horario_Bach!$M$2:$M$1200,$H25)) | H25: =IFERROR(MATCH($L$7&"|"&A25,Horario_Bach!$P$2:$P$1200,0),"")
... A73: 60 | B73: =IF($H73="","",INDEX(Horario_Bach!$L$2:$L$1200,$H73)) | C73: =IF($H73="","",INDEX(Horario_Bach!$B$2:$B$1200,$H73)) | D73: =IF($H73="","",INDEX(Horario_Bach!$H$2:$H$1200,$H73)) | E73: =IF($H73="","",IF(INDEX(Horario_Bach!$F$2:$F$1200,$H73)="ENFASIS","Énfasis","Clase")) | F73: =IF($H73="","",INDEX(Horario_Bach!$M$2:$M$1200,$H73)) | H73: =IFERROR(MATCH($L$7&"|"&A73,Horario_Bach!$P$2:$P$1200,0),"")

Sheet Por_Docente
A1: DÓNDE ESTÁ CADA DOCENTE · BACHILLERATO
A2: Usa la misma fecha, bloque y sesión de la hoja Ubicacion.
A3: Consulta | B3: =Ubicacion!B7
A4: Franja | B4: =Ubicacion!B8
A5: Estado | B5: =Ubicacion!B9
A7: Docente | B7: Dónde está (grupo) | C7: Área | D7: Tipo | E7: n
A8: Aguirre Riascos Jorge Andrés | B8: =IF(NOT(ISNUMBER(Ubicacion!$L$6)),"—",IFERROR(INDEX(Horario_Bach!$L$2:$L$1200,MATCH(Ubicacion!$L$2&"|"&Ubicacion!$L$6&"|"&$E8,Horario_Bach!$Q$2:$Q$1200,0)),"Libre (sin clase)")) | C8: =IF(NOT(ISNUMBER(Ubicacion!$L$6)),"",IFERROR(INDEX(Horario_Bach!$H$2:$H$1200,MATCH(Ubicacion!$L$2&"|"&Ubicacion!$L$6&"|"&$E8,Horario_Bach!$Q$2:$Q$1200,0)),"")) | D8: =IF(NOT(ISNUMBER(Ubicacion!$L$6)),"",IFERROR(IF(INDEX(Horario_Bach!$F$2:$F$1200,MATCH(Ubicacion!$L$2&"|"&Ubicacion!$L$6&"|"&$E8,Horario_Bach!$Q$2:$Q$1200,0))="ENFASIS","Énfasis","Clase"),"")) | E8: 1
A9: Angulo Lucero Andrés Mauricio | B9: =IF(NOT(ISNUMBER(Ubicacion!$L$6)),"—",IFERROR(INDEX(Horario_Bach!$L$2:$L$1200,MATCH(Ubicacion!$L$2&"|"&Ubicacion!$L$6&"|"&$E9,Horario_Bach!$Q$2:$Q$1200,0)),"Libre (sin clase)")) | C9: =IF(NOT(ISNUMBER(Ubicacion!$L$6)),"",IFERROR(INDEX(Horario_Bach!$H$2:$H$1200,MATCH(Ubicacion!$L$2&"|"&Ubicacion!$L$6&"|"&$E9,Horario_Bach!$Q$2:$Q$1200,0)),"")) | D9: =IF(NOT(ISNUMBER(Ubicacion!$L$6)),"",IFERROR(IF(INDEX(Horario_Bach!$F$2:$F$1200,MATCH(Ubicacion!$L$2&"|"&Ubicacion!$L$6&"|"&$E9,Horario_Bach!$Q$2:$Q$1200,0))="ENFASIS","Énfasis","Clase"),"")) | E9: 2
A10: Arboleda Ortiz Luz América | B10: =IF(NOT(ISNUMBER(Ubicacion!$L$6)),"—",IFERROR(INDEX(Horario_Bach!$L$2:$L$1200,MATCH(Ubicacion!$L$2&"|"&Ubicacion!$L$6&"|"&$E10,Horario_Bach!$Q$2:$Q$1200,0)),"Libre (sin clase)")) | C10: =IF(NOT(ISNUMBER(Ubicacion!$L$6)),"",IFERROR(INDEX(Horario_Bach!$H$2:$H$1200,MATCH(Ubicacion!$L$2&"|"&Ubicacion!$L$6&"|"&$E10,Horario_Bach!$Q$2:$Q$1200,0)),"")) | D10: =IF(NOT(ISNUMBER(Ubicacion!$L$6)),"",IFERROR(IF(INDEX(Horario_Bach!$F$2:$F$1200,MATCH(Ubicacion!$L$2&"|"&Ubicacion!$L$6&"|"&$E10,Horario_Bach!$Q$2:$Q$1200,0))="ENFASIS","Énfasis","Clase"),"")) | E10: 3
A11: Arizala Castro Roberto Carlos | B11: =IF(NOT(ISNUMBER(Ubicacion!$L$6)),"—",IFERROR(INDEX(Horario_Bach!$L$2:$L$1200,MATCH(Ubicacion!$L$2&"|"&Ubicacion!$L$6&"|"&$E11,Horario_Bach!$Q$2:$Q$1200,0)),"Libre (sin clase)")) | C11: =IF(NOT(ISNUMBER(Ubicacion!$L$6)),"",IFERROR(INDEX(Horario_Bach!$H$2:$H$1200,MATCH(Ubicacion!$L$2&"|"&Ubicacion!$L$6&"|"&$E11,Horario_Bach!$Q$2:$Q$1200,0)),"")) | D11: =IF(NOT(ISNUMBER(Ubicacion!$L$6)),"",IFERROR(IF(INDEX(Horario_Bach!$F$2:$F$1200,MATCH(Ubicacion!$L$2&"|"&Ubicacion!$L$6&"|"&$E11,Horario_Bach!$Q$2:$Q$1200,0))="ENFASIS","Énfasis","Clase"),"")) | E11: 4
A12: Armero Dájome Jesús | B12: =IF(NOT(ISNUMBER(Ubicacion!$L$6)),"—",IFERROR(INDEX(Horario_Bach!$L$2:$L$1200,MATCH(Ubicacion!$L$2&"|"&Ubicacion!$L$6&"|"&$E12,Horario_Bach!$Q$2:$Q$1200,0)),"Libre (sin clase)")) | C12: =IF(NOT(ISNUMBER(Ubicacion!$L$6)),"",IFERROR(INDEX(Horario_Bach!$H$2:$H$1200,MATCH(Ubicacion!$L$2&"|"&Ubicacion!$L$6&"|"&$E12,Horario_Bach!$Q$2:$Q$1200,0)),"")) | D12: =IF(NOT(ISNUMBER(Ubicacion!$L$6)),"",IFERROR(IF(INDEX(Horario_Bach!$F$2:$F$1200,MATCH(Ubicacion!$L$2&"|"&Ubicacion!$L$6&"|"&$E12,Horario_Bach!$Q$2:$Q$1200,0))="ENFASIS","Énfasis","Clase"),"")) | E12: 57
A13: Bastidas Valencia Zeneida Judith | B13: =IF(NOT(ISNUMBER(Ubicacion!$L$6)),"—",IFERROR(INDEX(Horario_Bach!$L$2:$L$1200,MATCH(Ubicacion!$L$2&"|"&Ubicacion!$L$6&"|"&$E13,Horario_Bach!$Q$2:$Q$1200,0)),"Libre (sin clase)")) | C13: =IF(NOT(ISNUMBER(Ubicacion!$L$6)),"",IFERROR(INDEX(Horario_Bach!$H$2:$H$1200,MATCH(Ubicacion!$L$2&"|"&Ubicacion!$L$6&"|"&$E13,Horario_Bach!$Q$2:$Q$1200,0)),"")) | D13: =IF(NOT(ISNUMBER(Ubicacion!$L$6)),"",IFERROR(IF(INDEX(Horario_Bach!$F$2:$F$1200,MATCH(Ubicacion!$L$2&"|"&Ubicacion!$L$6&"|"&$E13,Horario_Bach!$Q$2:$Q$1200,0))="ENFASIS","Énfasis","Clase"),"")) | E13: 5
A14: Betancourth Ocampo Yohana Patricia | B14: =IF(NOT(ISNUMBER(Ubicacion!$L$6)),"—",IFERROR(INDEX(Horario_Bach!$L$2:$L$1200,MATCH(Ubicacion!$L$2&"|"&Ubicacion!$L$6&"|"&$E14,Horario_Bach!$Q$2:$Q$1200,0)),"Libre (sin clase)")) | C14: =IF(NOT(ISNUMBER(Ubicacion!$L$6)),"",IFERROR(INDEX(Horario_Bach!$H$2:$H$1200,MATCH(Ubicacion!$L$2&"|"&Ubicacion!$L$6&"|"&$E14,Horario_Bach!$Q$2:$Q$1200,0)),"")) | D14: =IF(NOT(ISNUMBER(Ubicacion!$L$6)),"",IFERROR(IF(INDEX(Horario_Bach!$F$2:$F$1200,MATCH(Ubicacion!$L$2&"|"&Ubicacion!$L$6&"|"&$E14,Horario_Bach!$Q$2:$Q$1200,0))="ENFASIS","Énfasis","Clase"),"")) | E14: 6
A15: Casanova Quiñones Yoli del Carmen | B15: =IF(NOT(ISNUMBER(Ubicacion!$L$6)),"—",IFERROR(INDEX(Horario_Bach!$L$2:$L$1200,MATCH(Ubicacion!$L$2&"|"&Ubicacion!$L$6&"|"&$E15,Horario_Bach!$Q$2:$Q$1200,0)),"Libre (sin clase)")) | C15: =IF(NOT(ISNUMBER(Ubicacion!$L$6)),"",IFERROR(INDEX(Horario_Bach!$H$2:$H$1200,MATCH(Ubicacion!$L$2&"|"&Ubicacion!$L$6&"|"&$E15,Horario_Bach!$Q$2:$Q$1200,0)),"")) | D15: =IF(NOT(ISNUMBER(Ubicacion!$L$6)),"",IFERROR(IF(INDEX(Horario_Bach!$F$2:$F$1200,MATCH(Ubicacion!$L$2&"|"&Ubicacion!$L$6&"|"&$E15,Horario_Bach!$Q$2:$Q$1200,0))="ENFASIS","Énfasis","Clase"),"")) | E15: 8
A16: Castillo Angulo Martha Cecilia | B16: =IF(NOT(ISNUMBER(Ubicacion!$L$6)),"—",IFERROR(INDEX(Horario_Bach!$L$2:$L$1200,MATCH(Ubicacion!$L$2&"|"&Ubicacion!$L$6&"|"&$E16,Horario_Bach!$Q$2:$Q$1200,0)),"Libre (sin clase)")) | C16: =IF(NOT(ISNUMBER(Ubicacion!$L$6)),"",IFERROR(INDEX(Horario_Bach!$H$2:$H$1200,MATCH(Ubicacion!$L$2&"|"&Ubicacion!$L$6&"|"&$E16,Horario_Bach!$Q$2:$Q$1200,0)),"")) | D16: =IF(NOT(ISNUMBER(Ubicacion!$L$6)),"",IFERROR(IF(INDEX(Horario_Bach!$F$2:$F$1200,MATCH(Ubicacion!$L$2&"|"&Ubicacion!$L$6&"|"&$E16,Horario_Bach!$Q$2:$Q$1200,0))="ENFASIS","Énfasis","Clase"),"")) | E16: 9
A17: Castillo Cuero Daira Eneida | B17: =IF(NOT(ISNUMBER(Ubicacion!$L$6)),"—",IFERROR(INDEX(Horario_Bach!$L$2:$L$1200,MATCH(Ubicacion!$L$2&"|"&Ubicacion!$L$6&"|"&$E17,Horario_Bach!$Q$2:$Q$1200,0)),"Libre (sin clase)")) | C17: =IF(NOT(ISNUMBER(Ubicacion!$L$6)),"",IFERROR(INDEX(Horario_Bach!$H$2:$H$1200,MATCH(Ubicacion!$L$2&"|"&Ubicacion!$L$6&"|"&$E17,Horario_Bach!$Q$2:$Q$1200,0)),"")) | D17: =IF(NOT(ISNUMBER(Ubicacion!$L$6)),"",IFERROR(IF(INDEX(Horario_Bach!$F$2:$F$1200,MATCH(Ubicacion!$L$2&"|"&Ubicacion!$L$6&"|"&$E17,Horario_Bach!$Q$2:$Q$1200,0))="ENFASIS","Énfasis","Clase"),"")) | E17: 10
A18: Chillambo Quiñones María Rocío | B18: =IF(NOT(ISNUMBER(Ubicacion!$L$6)),"—",IFERROR(INDEX(Horario_Bach!$L$2:$L$1200,MATCH(Ubicacion!$L$2&"|"&Ubicacion!$L$6&"|"&$E18,Horario_Bach!$Q$2:$Q$1200,0)),"Libre (sin clase)")) | C18: =IF(NOT(ISNUMBER(Ubicacion!$L$6)),"",IFERROR(INDEX(Horario_Bach!$H$2:$H$1200,MATCH(Ubicacion!$L$2&"|"&Ubicacion!$L$6&"|"&$E18,Horario_Bach!$Q$2:$Q$1200,0)),"")) | D18: =IF(NOT(ISNUMBER(Ubicacion!$L$6)),"",IFERROR(IF(INDEX(Horario_Bach!$F$2:$F$1200,MATCH(Ubicacion!$L$2&"|"&Ubicacion!$L$6&"|"&$E18,Horario_Bach!$Q$2:$Q$1200,0))="ENFASIS","Énfasis","Clase"),"")) | E18: 12
A19: Cuero Bamba Berte Levi | B19: =IF(NOT(ISNUMBER(Ubicacion!$L$6)),"—",IFERROR(INDEX(Horario_Bach!$L$2:$L$1200,MATCH(Ubicacion!$L$2&"|"&Ubicacion!$L$6&"|"&$E19,Horario_Bach!$Q$2:$Q$1200,0)),"Libre (sin clase)")) | C19: =IF(NOT(ISNUMBER(Ubicacion!$L$6)),"",IFERROR(INDEX(Horario_Bach!$H$2:$H$1200,MATCH(Ubicacion!$L$2&"|"&Ubicacion!$L$6&"|"&$E19,Horario_Bach!$Q$2:$Q$1200,0)),"")) | D19: =IF(NOT(ISNUMBER(Ubicacion!$L$6)),"",IFERROR(IF(INDEX(Horario_Bach!$F$2:$F$1200,MATCH(Ubicacion!$L$2&"|"&Ubicacion!$L$6&"|"&$E19,Horario_Bach!$Q$2:$Q$1200,0))="ENFASIS","Énfasis","Clase"),"")) | E19: 15
... A45: Vásquez Valencia Segundo Leoncio | B45: =IF(NOT(ISNUMBER(Ubicacion!$L$6)),"—",IFERROR(INDEX(Horario_Bach!$L$2:$L$1200,MATCH(Ubicacion!$L$2&"|"&Ubicacion!$L$6&"|"&$E45,Horario_Bach!$Q$2:$Q$1200,0)),"Libre (sin clase)")) | C45: =IF(NOT(ISNUMBER(Ubicacion!$L$6)),"",IFERROR(INDEX(Horario_Bach!$H$2:$H$1200,MATCH(Ubicacion!$L$2&"|"&Ubicacion!$L$6&"|"&$E45,Horario_Bach!$Q$2:$Q$1200,0)),"")) | D45: =IF(NOT(ISNUMBER(Ubicacion!$L$6)),"",IFERROR(IF(INDEX(Horario_Bach!$F$2:$F$1200,MATCH(Ubicacion!$L$2&"|"&Ubicacion!$L$6&"|"&$E45,Horario_Bach!$Q$2:$Q$1200,0))="ENFASIS","Énfasis","Clase"),"")) | E45: 52

Sheet Horario_Bach
A1: docente_n | B1: docente | C1: dia | D1: sesion | E1: bloque | F1: tipo | G1: grupo | H1: area | I1: grupos_enfasis | J1: alternancia | K1: equipo_enfasis | L1: grupo_mostrar | M1: nota | N1: clave | O1: orden | P1: indice | Q1: clave_docente
A2: 37 | B2: Prado Quiñones Genís Maribel | C2: LUNES | D2: 1 | E2: 1 | F2: CLASE | G2: 0601 | H2: ART | L2: 6°-1 | N2: =C2&"|"&D2 | O2: =COUNTIF($N$2:N2,N2) | P2: =N2&"|"&O2 | Q2: =C2&"|"&D2&"|"&A2
A3: 26 | B3: Lozano Torres Amanda Inés | C3: LUNES | D3: 1 | E3: 1 | F3: CLASE | G3: 0602 | H3: ETR | J3: Ética / Religión (alternan cada semana) | L3: 6°-2 | M3: Ética / Religión (alternan cada semana) | N3: =C3&"|"&D3 | O3: =COUNTIF($N$2:N3,N3) | P3: =N3&"|"&O3 | Q3: =C3&"|"&D3&"|"&A3
A4: 39 | B4: Puches Ana Milena | C4: LUNES | D4: 1 | E4: 1 | F4: CLASE | G4: 0704 | H4: ART | L4: 7°-4 | N4: =C4&"|"&D4 | O4: =COUNTIF($N$2:N4,N4) | P4: =N4&"|"&O4 | Q4: =C4&"|"&D4&"|"&A4
A5: 35 | B5: Ortiz Araujo Adiela Carlota | C5: LUNES | D5: 1 | E5: 1 | F5: CLASE | G5: 0801 | H5: CSI | J5: Sociales / Inglés (alternan cada semana) | L5: 8°-1 | M5: Sociales / Inglés (alternan cada semana) | N5: =C5&"|"&D5 | O5: =COUNTIF($N$2:N5,N5) | P5: =N5&"|"&O5 | Q5: =C5&"|"&D5&"|"&A5
A6: 15 | B6: Cuero Bamba Berte Levi | C6: LUNES | D6: 1 | E6: 1 | F6: CLASE | G6: 0802 | H6: ERD | L6: 8°-2 | N6: =C6&"|"&D6 | O6: =COUNTIF($N$2:N6,N6) | P6: =N6&"|"&O6 | Q6: =C6&"|"&D6&"|"&A6
A7: 6 | B7: Betancourth Ocampo Yohana Patricia | C7: LUNES | D7: 1 | E7: 1 | F7: CLASE | G7: 0901 | H7: CSI | J7: Sociales / Inglés (alternan cada semana) | L7: 9°-1 | M7: Sociales / Inglés (alternan cada semana) | N7: =C7&"|"&D7 | O7: =COUNTIF($N$2:N7,N7) | P7: =N7&"|"&O7 | Q7: =C7&"|"&D7&"|"&A7
A8: 49 | B8: Valencia Marínez Saidy Eufemia | C8: LUNES | D8: 1 | E8: 1 | F8: CLASE | G8: 0902 | H8: ART | L8: 9°-2 | N8: =C8&"|"&D8 | O8: =COUNTIF($N$2:N8,N8) | P8: =N8&"|"&O8 | Q8: =C8&"|"&D8&"|"&A8
A9: 31 | B9: Montaño Arizala Leidis Claudina | C9: LUNES | D9: 1 | E9: 1 | F9: CLASE | G9: 1002 | H9: ETR | J9: Ética / Religión (alternan cada semana) | L9: 10°-2 | M9: Ética / Religión (alternan cada semana) | N9: =C9&"|"&D9 | O9: =COUNTIF($N$2:N9,N9) | P9: =N9&"|"&O9 | Q9: =C9&"|"&D9&"|"&A9
A10: 2 | B10: Angulo Lucero Andrés Mauricio | C10: LUNES | D10: 1 | E10: 1 | F10: CLASE | G10: 1101 | H10: TEI | L10: 11°-1 | N10: =C10&"|"&D10 | O10: =COUNTIF($N$2:N10,N10) | P10: =N10&"|"&O10 | Q10: =C10&"|"&D10&"|"&A10
A11: 40 | B11: Pulgarín Ortiz César Marino | C11: LUNES | D11: 1 | E11: 1 | F11: CLASE | G11: 1102 | H11: CSI | J11: Sociales / Inglés (alternan cada semana) | L11: 11°-2 | M11: Sociales / Inglés (alternan cada semana) | N11: =C11&"|"&D11 | O11: =COUNTIF($N$2:N11,N11) | P11: =N11&"|"&O11 | Q11: =C11&"|"&D11&"|"&A11
A12: 16 | B12: Cuero Rincón Hernando Jesús | C12: LUNES | D12: 1 | E12: 1 | F12: CLASE | G12: CS101 | H12: CAS | L12: CS 1-1 | N12: =C12&"|"&D12 | O12: =COUNTIF($N$2:N12,N12) | P12: =N12&"|"&O12 | Q12: =C12&"|"&D12&"|"&A12
A13: 42 | B13: Quiñones Cabezas Marcos Vidal | C13: LUNES | D13: 1 | E13: 1 | F13: CLASE | G13: CS102 | H13: TEI | L13: CS 1-2 | N13: =C13&"|"&D13 | O13: =COUNTIF($N$2:N13,N13) | P13: =N13&"|"&O13 | Q13: =C13&"|"&D13&"|"&A13
A14: 19 | B14: Fernández Vélez Alfredo Enrique | C14: LUNES | D14: 1 | E14: 1 | F14: CLASE | G14: CS201 | H14: TEI | L14: CS 2-1 | N14: =C14&"|"&D14 | O14: =COUNTIF($N$2:N14,N14) | P14: =N14&"|"&O14 | Q14: =C14&"|"&D14&"|"&A14
A15: 12 | B15: Chillambo Quiñones María Rocío | C15: LUNES | D15: 1 | E15: 1 | F15: CLASE | G15: CS202 | H15: CNA | L15: CS 2-2 | N15: =C15&"|"&D15 | O15: =COUNTIF($N$2:N15,N15) | P15: =N15&"|"&O15 | Q15: =C15&"|"&D15&"|"&A15
A16: 44 | B16: Samaniego Angulo Flor Mireya | C16: LUNES | D16: 1 | E16: 1 | F16: ENFASIS | H16: ART | I16: 0701 | J16: PAREJA: comparten el énfasis y alternan por semana | K16: Valverde Montaño María Teresa (CAS) | L16: ÉNFASIS 7°-1 | M16: PAREJA: comparten el énfasis y alternan por semana · Con: Valverde Montaño María Teresa (CAS) | N16: =C16&"|"&D16 | O16: =COUNTIF($N$2:N16,N16) | P16: =N16&"|"&O16 | Q16: =C16&"|"&D16&"|"&A16
A17: 51 | B17: Valverde Montaño María Teresa | C17: LUNES | D17: 1 | E17: 1 | F17: ENFASIS | H17: CAS | I17: 0701 | J17: PAREJA: comparten el énfasis y alternan por semana | K17: Samaniego Angulo Flor Mireya (ART) | L17: ÉNFASIS 7°-1 | M17: PAREJA: comparten el énfasis y alternan por semana · Con: Samaniego Angulo Flor Mireya (ART) | N17: =C17&"|"&D17 | O17: =COUNTIF($N$2:N17,N17) | P17: =N17&"|"&O17 | Q17: =C17&"|"&D17&"|"&A17
A18: 34 | B18: Ordóñez Tenorio Jaime Marcial | C18: LUNES | D18: 1 | E18: 1 | F18: ENFASIS | H18: CNA | I18: 0702 | J18: PAREJA: comparten el énfasis y alternan por semana | K18: Armero Dájome Jesús (ERD) | L18: ÉNFASIS 7°-2 | M18: PAREJA: comparten el énfasis y alternan por semana · Con: Armero Dájome Jesús (ERD) | N18: =C18&"|"&D18 | O18: =COUNTIF($N$2:N18,N18) | P18: =N18&"|"&O18 | Q18: =C18&"|"&D18&"|"&A18
A19: 4 | B19: Arizala Castro Roberto Carlos | C19: LUNES | D19: 1 | E19: 1 | F19: ENFASIS | H19: ERD | I19: 0702 | J19: PAREJA: comparten el énfasis y alternan por semana | K19: Ordóñez Tenorio Jaime Marcial (CNA) | L19: ÉNFASIS 7°-2 | M19: PAREJA: comparten el énfasis y alternan por semana · Con: Ordóñez Tenorio Jaime Marcial (CNA) | N19: =C19&"|"&D19 | O19: =COUNTIF($N$2:N19,N19) | P19: =N19&"|"&O19 | Q19: =C19&"|"&D19&"|"&A19
A20: 8 | B20: Casanova Quiñones Yoli del Carmen | C20: LUNES | D20: 1 | E20: 1 | F20: ENFASIS | H20: ETR | I20: 0703 | J20: PAREJA: comparten el énfasis y alternan por semana | K20: Quintero Ramírez María del Carmen (CSI) | L20: ÉNFASIS 7°-3 | M20: PAREJA: comparten el énfasis y alternan por semana · Con: Quintero Ramírez María del Carmen (CSI) | N20: =C20&"|"&D20 | O20: =COUNTIF($N$2:N20,N20) | P20: =N20&"|"&O20 | Q20: =C20&"|"&D20&"|"&A20
A21: 41 | B21: Quintero Ramírez María del Carmen | C21: LUNES | D21: 1 | E21: 1 | F21: ENFASIS | H21: CSI | I21: 0703 | J21: PAREJA: comparten el énfasis y alternan por semana | K21: Casanova Quiñones Yoli del Carmen (ETR) | L21: ÉNFASIS 7°-3 | M21: PAREJA: comparten el énfasis y alternan por semana · Con: Casanova Quiñones Yoli del Carmen (ETR) | N21: =C21&"|"&D21 | O21: =COUNTIF($N$2:N21,N21) | P21: =N21&"|"&O21 | Q21: =C21&"|"&D21&"|"&A21
A22: 3 | B22: Arboleda Ortiz Luz América | C22: LUNES | D22: 1 | E22: 1 | F22: ENFASIS | H22: ART | I22: 1001 | J22: EQUIPO DE 4: cada docente atiende un grupo de estudiantes en su área | K22: Montaño Anchico Favio Héctor (CAS); Ramírez Guerra Jimmy Eduardo (ERD); Villota Rubio Héctor Hugo (CNA) | L22: ÉNFASIS 10°-1 | M22: EQUIPO DE 4: cada docente atiende un grupo de estudiantes en su área · Con: Montaño Anchico Favio Héctor (CAS); Ramírez Guerra Jimmy Eduardo (ERD); Villota Rubio Héctor Hugo (CNA) | N22: =C22&"|"&D22 | O22: =COUNTIF($N$2:N22,N22) | P22: =N22&"|"&O22 | Q22: =C22&"|"&D22&"|"&A22
A23: 30 | B23: Montaño Anchico Favio Héctor | C23: LUNES | D23: 1 | E23: 1 | F23: ENFASIS | H23: CAS | I23: 1001 | J23: EQUIPO DE 4: cada docente atiende un grupo de estudiantes en su área | K23: Arboleda Ortiz Luz América (ART); Ramírez Guerra Jimmy Eduardo (ERD); Villota Rubio Héctor Hugo (CNA) | L23: ÉNFASIS 10°-1 | M23: EQUIPO DE 4: cada docente atiende un grupo de estudiantes en su área · Con: Arboleda Ortiz Luz América (ART); Ramírez Guerra Jimmy Eduardo (ERD); Villota Rubio Héctor Hugo (CNA) | N23: =C23&"|"&D23 | O23: =COUNTIF($N$2:N23,N23) | P23: =N23&"|"&O23 | Q23: =C23&"|"&D23&"|"&A23
A24: 43 | B24: Ramírez Guerra Jimmy Eduardo | C24: LUNES | D24: 1 | E24: 1 | F24: ENFASIS | H24: ERD | I24: 1001 | J24: EQUIPO DE 4: cada docente atiende un grupo de estudiantes en su área | K24: Arboleda Ortiz Luz América (ART); Montaño Anchico Favio Héctor (CAS); Villota Rubio Héctor Hugo (CNA) | L24: ÉNFASIS 10°-1 | M24: EQUIPO DE 4: cada docente atiende un grupo de estudiantes en su área · Con: Arboleda Ortiz Luz América (ART); Montaño Anchico Favio Héctor (CAS); Villota Rubio Héctor Hugo (CNA) | N24: =C24&"|"&D24 | O24: =COUNTIF($N$2:N24,N24) | P24: =N24&"|"&O24 | Q24: =C24&"|"&D24&"|"&A24
A25: 53 | B25: Villota Rubio Héctor Hugo | C25: LUNES | D25: 1 | E25: 1 | F25: ENFASIS | H25: CNA | I25: 1001 | J25: EQUIPO DE 4: cada docente atiende un grupo de estudiantes en su área | K25: Arboleda Ortiz Luz América (ART); Montaño Anchico Favio Héctor (CAS); Ramírez Guerra Jimmy Eduardo (ERD) | L25: ÉNFASIS 10°-1 | M25: EQUIPO DE 4: cada docente atiende un grupo de estudiantes en su área · Con: Arboleda Ortiz Luz América (ART); Montaño Anchico Favio Héctor (CAS); Ramírez Guerra Jimmy Eduardo (ERD) | N25: =C25&"|"&D25 | O25: =COUNTIF($N$2:N25,N25) | P25: =N25&"|"&O25 | Q25: =C25&"|"&D25&"|"&A25
A26: 37 | B26: Prado Quiñones Genís Maribel | C26: LUNES | D26: 2 | E26: 1 | F26: CLASE | G26: 0601 | H26: ART | L26: 6°-1 | N26: =C26&"|"&D26 | O26: =COUNTIF($N$2:N26,N26) | P26: =N26&"|"&O26 | Q26: =C26&"|"&D26&"|"&A26
A27: 26 | B27: Lozano Torres Amanda Inés | C27: LUNES | D27: 2 | E27: 1 | F27: CLASE | G27: 0602 | H27: ETR | J27: Ética / Religión (alternan cada semana) | L27: 6°-2 | M27: Ética / Religión (alternan cada semana) | N27: =C27&"|"&D27 | O27: =COUNTIF($N$2:N27,N27) | P27: =N27&"|"&O27 | Q27: =C27&"|"&D27&"|"&A27
A28: 39 | B28: Puches Ana Milena | C28: LUNES | D28: 2 | E28: 1 | F28: CLASE | G28: 0704 | H28: ART | L28: 7°-4 | N28: =C28&"|"&D28 | O28: =COUNTIF($N$2:N28,N28) | P28: =N28&"|"&O28 | Q28: =C28&"|"&D28&"|"&A28
A29: 35 | B29: Ortiz Araujo Adiela Carlota | C29: LUNES | D29: 2 | E29: 1 | F29: CLASE | G29: 0801 | H29: CSI | J29: Sociales / Inglés (alternan cada semana) | L29: 8°-1 | M29: Sociales / Inglés (alternan cada semana) | N29: =C29&"|"&D29 | O29: =COUNTIF($N$2:N29,N29) | P29: =N29&"|"&O29 | Q29: =C29&"|"&D29&"|"&A29
A30: 15 | B30: Cuero Bamba Berte Levi | C30: LUNES | D30: 2 | E30: 1 | F30: CLASE | G30: 0802 | H30: ERD | L30: 8°-2 | N30: =C30&"|"&D30 | O30: =COUNTIF($N$2:N30,N30) | P30: =N30&"|"&O30 | Q30: =C30&"|"&D30&"|"&A30
A31: 6 | B31: Betancourth Ocampo Yohana Patricia | C31: LUNES | D31: 2 | E31: 1 | F31: CLASE | G31: 0901 | H31: CSI | J31: Sociales / Inglés (alternan cada semana) | L31: 9°-1 | M31: Sociales / Inglés (alternan cada semana) | N31: =C31&"|"&D31 | O31: =COUNTIF($N$2:N31,N31) | P31: =N31&"|"&O31 | Q31: =C31&"|"&D31&"|"&A31
A32: 49 | B32: Valencia Marínez Saidy Eufemia | C32: LUNES | D32: 2 | E32: 1 | F32: CLASE | G32: 0902 | H32: ART | L32: 9°-2 | N32: =C32&"|"&D32 | O32: =COUNTIF($N$2:N32,N32) | P32: =N32&"|"&O32 | Q32: =C32&"|"&D32&"|"&A32
A33: 31 | B33: Montaño Arizala Leidis Claudina | C33: LUNES | D33: 2 | E33: 1 | F33: CLASE | G33: 1002 | H33: ETR | J33: Ética / Religión (alternan cada semana) | L33: 10°-2 | M33: Ética / Religión (alternan cada semana) | N33: =C33&"|"&D33 | O33: =COUNTIF($N$2:N33,N33) | P33: =N33&"|"&O33 | Q33: =C33&"|"&D33&"|"&A33
A34: 2 | B34: Angulo Lucero Andrés Mauricio | C34: LUNES | D34: 2 | E34: 1 | F34: CLASE | G34: 1101 | H34: TEI | L34: 11°-1 | N34: =C34&"|"&D34 | O34: =COUNTIF($N$2:N34,N34) | P34: =N34&"|"&O34 | Q34: =C34&"|"&D34&"|"&A34
A35: 40 | B35: Pulgarín Ortiz César Marino | C35: LUNES | D35: 2 | E35: 1 | F35: CLASE | G35: 1102 | H35: CSI | J35: Sociales / Inglés (alternan cada semana) | L35: 11°-2 | M35: Sociales / Inglés (alternan cada semana) | N35: =C35&"|"&D35 | O35: =COUNTIF($N$2:N35,N35) | P35: =N35&"|"&O35 | Q35: =C35&"|"&D35&"|"&A35
A36: 16 | B36: Cuero Rincón Hernando Jesús | C36: LUNES | D36: 2 | E36: 1 | F36: CLASE | G36: CS101 | H36: CAS | L36: CS 1-1 | N36: =C36&"|"&D36 | O36: =COUNTIF($N$2:N36,N36) | P36: =N36&"|"&O36 | Q36: =C36&"|"&D36&"|"&A36
A37: 42 | B37: Quiñones Cabezas Marcos Vidal | C37: LUNES | D37: 2 | E37: 1 | F37: CLASE | G37: CS102 | H37: TEI | L37: CS 1-2 | N37: =C37&"|"&D37 | O37: =COUNTIF($N$2:N37,N37) | P37: =N37&"|"&O37 | Q37: =C37&"|"&D37&"|"&A37
A38: 19 | B38: Fernández Vélez Alfredo Enrique | C38: LUNES | D38: 2 | E38: 1 | F38: CLASE | G38: CS201 | H38: TEI | L38: CS 2-1 | N38: =C38&"|"&D38 | O38: =COUNTIF($N$2:N38,N38) | P38: =N38&"|"&O38 | Q38: =C38&"|"&D38&"|"&A38
A39: 12 | B39: Chillambo Quiñones María Rocío | C39: LUNES | D39: 2 | E39: 1 | F39: CLASE | G39: CS202 | H39: CNA | L39: CS 2-2 | N39: =C39&"|"&D39 | O39: =COUNTIF($N$2:N39,N39) | P39: =N39&"|"&O39 | Q39: =C39&"|"&D39&"|"&A39
A40: 44 | B40: Samaniego Angulo Flor Mireya | C40: LUNES | D40: 2 | E40: 1 | F40: ENFASIS | H40: ART | I40: 0701 | J40: PAREJA: comparten el énfasis y alternan por semana | K40: Valverde Montaño María Teresa (CAS) | L40: ÉNFASIS 7°-1 | M40: PAREJA: comparten el énfasis y alternan por semana · Con: Valverde Montaño María Teresa (CAS) | N40: =C40&"|"&D40 | O40: =COUNTIF($N$2:N40,N40) | P40: =N40&"|"&O40 | Q40: =C40&"|"&D40&"|"&A40
...

Sheet Franjas
A1: sesion | B1: bloque | C1: inicio | D1: fin | E1: inicio_min | F1: fin_min
A2: 1 | B2: 1 | C2: 06:30 | D2: 07:15 | E2: 390 | F2: 435
A3: 2 | B3: 1 | C3: 07:15 | D3: 08:00 | E3: 435 | F3: 480
A4: 3 | B4: 2 | C4: 08:20 | D4: 09:05 | E4: 500 | F4: 545
A5: 4 | B5: 2 | C5: 09:05 | D5: 09:50 | E5: 545 | F5: 590
A6: 5 | B6: 3 | C6: 10:10 | D6: 10:55 | E6: 610 | F6: 655
A7: 6 | B7: 3 | C7: 10:55 | D7: 11:40 | E7: 655 | F7: 700
A8: 7 | B8: 4 | C8: 12:00 | D8: 12:45 | E8: 720 | F8: 765
A9: 8 | B9: 4 | C9: 12:45 | D9: 13:30 | E9: 765 | F9: 810

Sheet Grupos
A1: grupo | B1: nombre | C1: modalidad
A2: 0601 | B2: 6°-1
A3: 0602 | B3: 6°-2
A4: CS101 | B4: CS 1-1
A5: CS102 | B5: CS 1-2
A6: 0701 | B6: 7°-1
A7: 0702 | B7: 7°-2
A8: 0703 | B8: 7°-3
A9: 0704 | B9: 7°-4
A10: 0801 | B10: 8°-1
A11: 0802 | B11: 8°-2
A12: 0901 | B12: 9°-1
A13: 0902 | B13: 9°-2
... A19: 1102 | B19: 11°-2

Sheet LEEME
A1: ICET 2026 - Ubicación de docentes de bachillerato
A3: 1) Abra la hoja 'Ubicacion': muestra sola quién está en cada grupo en este momento (según la fecha y la hora del dispositivo).
A4: 2) Para otro momento escriba la fecha y elija un bloque (1 a 4) o una sesión (1 a 8) en las celdas amarillas. Vacías = ahora.
A5: 3) 'Por_Docente' lista a los docentes de A a Z y dónde está cada uno (o 'Libre') en el mismo momento.
A6: 4) Se muestran solo clases y énfasis de bachillerato (6° a 11° y Caminar en Secundaria). No incluye preescolar ni primaria.
A7: 5) Énfasis (fila amarilla): estudiantes del curso repartidos entre un equipo de docentes; cada uno atiende su área.
A9: Zona horaria: en Google Sheets use Archivo > Configuración > GMT-05:00 Bogotá. Excel usa la hora del dispositivo.
A10: Horario según el PDF de asignación del 02-02-2026 con los cambios del coordinador: Armero reemplaza a Terán; Prado y Puches intercambiaron Arte.
A11: Si cambia el horario, regenere con: python3 scripts/generar_ubicacion.py
